Workbook
Name notional: '1_Inputs'!$B$5
Name recovery: '1_Inputs'!$B$4
Name r_free: '1_Inputs'!$B$3

Sheet 1_Inputs
A1: CDS PRICING MODEL — INPUTS & HAZARD RATES
A2: ── MODEL PARAMETERS ── | D2: Tenor | E2: Spread (bps) | G2: Segment | H2: λ (input/seed) | I2: λ (bps) | J2: Model Spread(bps) | K2: Market Spread(bps)
A3: Risk-free rate (r) | B3: 0.03 | D3: 6m | E3: 70 | G3: 0→6m | H3: 0.011588203 | I3: =H3*10000 -> 115.88203 | J3: ='5_Pricing_Summary'!C3 -> 69.999913 | K3: =E3 -> 70
A4: Recovery rate (R) | B4: 0.4 | D4: 1y | E4: 90 | G4: 6m→1y | H4: 0.010938026 | I4: =H4*10000 -> 109.38026 | J4: ='5_Pricing_Summary'!C4 -> 89.999383 | K4: =E4 -> 90
A5: Notional (N) | B5: 10000000 | D5: 2y | E5: 110 | G5: 1→2y | H5: 0.02111475 | I5: =H5*10000 -> 211.1475 | J5: ='5_Pricing_Summary'!C5 -> 110 | K5: =E5 -> 110
D6: 3y | E6: 130 | G6: 2→3y | H6: 0.028212884 | I6: =H6*10000 -> 282.12884 | J6: ='5_Pricing_Summary'!C6 -> 130 | K6: =E6 -> 130
D7: 5y | E7: 150 | G7: 3→5y | H7: 0.030571282 | I7: =H7*10000 -> 305.71282 | J7: ='5_Pricing_Summary'!C7 -> 149.99998 | K7: =E7 -> 150
G9: To update after changing market spreads: use Excel Solver (Data→Solver) to set Col J = Col K for each tenor by changing Col H. Or use Goal Seek individually per tenor.
G11: HOW TO RECALIBRATE AFTER CHANGING SPREADS
G12: 1. Change market spreads in column E (amber cells).
G13: 2. Go to Data → Solver. Add constraints: J3=K3, J4=K4, J5=K5, J6=K6, J7=K7.
G14: 3. Set 'By Changing Variable Cells' to H3:H7. Click Solve.
G15: 4. All formulas in Sheets 2-6 update automatically.
G16: Alternative: Goal Seek each row individually (Data → What-If → Goal Seek).

Sheet 2_Discount_Factors
A1: DISCOUNT FACTORS — Daily Grid, 5 Years (1825 rows). df(t)=EXP(−r×t)
A2: Day j | B2: t (yrs) | C2: df(t)=EXP(−r×t) | D2: Notes
A3: 0 | B3: =A3/365 -> 0 | C3: =EXP(-r_free*B3) -> 1 | D3: t=0: df=1, Q=1 by definition
A4: 1 | B4: =A4/365 -> 0.002739726 | C4: =EXP(-r_free*B4) -> 0.99991781
A5: 2 | B5: =A5/365 -> 0.0054794521 | C5: =EXP(-r_free*B5) -> 0.99983563
A6: 3 | B6: =A6/365 -> 0.0082191781 | C6: =EXP(-r_free*B6) -> 0.99975346
A7: 4 | B7: =A7/365 -> 0.010958904 | C7: =EXP(-r_free*B7) -> 0.99967129
A8: 5 | B8: =A8/365 -> 0.01369863 | C8: =EXP(-r_free*B8) -> 0.99958913
A9: 6 | B9: =A9/365 -> 0.016438356 | C9: =EXP(-r_free*B9) -> 0.99950697
A10: 7 | B10: =A10/365 -> 0.019178082 | C10: =EXP(-r_free*B10) -> 0.99942482
A11: 8 | B11: =A11/365 -> 0.021917808 | C11: =EXP(-r_free*B11) -> 0.99934268
A12: 9 | B12: =A12/365 -> 0.024657534 | C12: =EXP(-r_free*B12) -> 0.99926055
A13: 10 | B13: =A13/365 -> 0.02739726 | C13: =EXP(-r_free*B13) -> 0.99917842
A14: 11 | B14: =A14/365 -> 0.030136986 | C14: =EXP(-r_free*B14) -> 0.9990963
A15: 12 | B15: =A15/365 -> 0.032876712 | C15: =EXP(-r_free*B15) -> 0.99901418
... A93: 90 | B93: =A93/365 -> 0.24657534 | C93: =EXP(-r_free*B93) -> 0.99263003
A94: 91 | B94: =A94/365 -> 0.24931507 | C94: =EXP(-r_free*B94) -> 0.99254845 | D94: Quarter end Q1
A95: 92 | B95: =A95/365 -> 0.25205479 | C95: =EXP(-r_free*B95) -> 0.99246687
A96: 93 | B96: =A96/365 -> 0.25479452 | C96: =EXP(-r_free*B96) -> 0.9923853
A97: 94 | B97: =A97/365 -> 0.25753425 | C97: =EXP(-r_free*B97) -> 0.99230374
A98: 95 | B98: =A98/365 -> 0.26027397 | C98: =EXP(-r_free*B98) -> 0.99222219
A99: 96 | B99: =A99/365 -> 0.2630137 | C99: =EXP(-r_free*B99) -> 0.99214064
A100: 97 | B100: =A100/365 -> 0.26575342 | C100: =EXP(-r_free*B100) -> 0.99205909
A101: 98 | B101: =A101/365 -> 0.26849315 | C101: =EXP(-r_free*B101) -> 0.99197756
A102: 99 | B102: =A102/365 -> 0.27123288 | C102: =EXP(-r_free*B102) -> 0.99189603
A103: 100 | B103: =A103/365 -> 0.2739726 | C103: =EXP(-r_free*B103) -> 0.99181451
A104: 101 | B104: =A104/365 -> 0.27671233 | C104: =EXP(-r_free*B104) -> 0.99173299
A105: 102 | B105: =A105/365 -> 0.27945205 | C105: =EXP(-r_free*B105) -> 0.99165148
A106: 103 | B106: =A106/365 -> 0.28219178 | C106: =EXP(-r_free*B106) -> 0.99156998
... A184: 181 | B184: =A184/365 -> 0.49589041 | C184: =EXP(-r_free*B184) -> 0.9852334
A185: 182 | B185: =A185/365 -> 0.49863014 | C185: =EXP(-r_free*B185) -> 0.98515242 | D185: Quarter end Q2
A186: 183 | B186: =A186/365 -> 0.50136986 | C186: =EXP(-r_free*B186) -> 0.98507146
A187: 184 | B187: =A187/365 -> 0.50410959 | C187: =EXP(-r_free*B187) -> 0.98499049
A188: 185 | B188: =A188/365 -> 0.50684932 | C188: =EXP(-r_free*B188) -> 0.98490954
A189: 186 | B189: =A189/365 -> 0.50958904 | C189: =EXP(-r_free*B189) -> 0.98482859
A190: 187 | B190: =A190/365 -> 0.51232877 | C190: =EXP(-r_free*B190) -> 0.98474765
A191: 188 | B191: =A191/365 -> 0.51506849 | C191: =EXP(-r_free*B191) -> 0.98466672
A192: 189 | B192: =A192/365 -> 0.51780822 | C192: =EXP(-r_free*B192) -> 0.98458579
A193: 190 | B193: =A193/365 -> 0.52054795 | C193: =EXP(-r_free*B193) -> 0.98450487
A194: 191 | B194: =A194/365 -> 0.52328767 | C194: =EXP(-r_free*B194) -> 0.98442395
...

Sheet 3_Survival_Probs
A1: SURVIVAL PROBABILITIES Q(t) — Daily. Piecewise: Q(t)=Q(t_prev)×EXP(−λₖ×Δt)
A2: Day j | B2: t (yrs) | C2: λ applicable | D2: Q(t) | E2: Notes
A3: 0 | B3: =A3/365 -> 0 | C3: ='1_Inputs'!$H$3 -> 0.011588203 | D3: =1 -> 1 | E3: Q(0)=1 by definition
A4: 1 | B4: =A4/365 -> 0.002739726 | C4: ='1_Inputs'!$H$3 -> 0.011588203 | D4: =D3*EXP(-'1_Inputs'!$H$3*(1/365)) -> 0.99996825
A5: 2 | B5: =A5/365 -> 0.0054794521 | C5: ='1_Inputs'!$H$3 -> 0.011588203 | D5: =D4*EXP(-'1_Inputs'!$H$3*(1/365)) -> 0.99993651
A6: 3 | B6: =A6/365 -> 0.0082191781 | C6: ='1_Inputs'!$H$3 -> 0.011588203 | D6: =D5*EXP(-'1_Inputs'!$H$3*(1/365)) -> 0.99990476
A7: 4 | B7: =A7/365 -> 0.010958904 | C7: ='1_Inputs'!$H$3 -> 0.011588203 | D7: =D6*EXP(-'1_Inputs'!$H$3*(1/365)) -> 0.99987301
A8: 5 | B8: =A8/365 -> 0.01369863 | C8: ='1_Inputs'!$H$3 -> 0.011588203 | D8: =D7*EXP(-'1_Inputs'!$H$3*(1/365)) -> 0.99984127
A9: 6 | B9: =A9/365 -> 0.016438356 | C9: ='1_Inputs'!$H$3 -> 0.011588203 | D9: =D8*EXP(-'1_Inputs'!$H$3*(1/365)) -> 0.99980953
A10: 7 | B10: =A10/365 -> 0.019178082 | C10: ='1_Inputs'!$H$3 -> 0.011588203 | D10: =D9*EXP(-'1_Inputs'!$H$3*(1/365)) -> 0.99977779
A11: 8 | B11: =A11/365 -> 0.021917808 | C11: ='1_Inputs'!$H$3 -> 0.011588203 | D11: =D10*EXP(-'1_Inputs'!$H$3*(1/365)) -> 0.99974604
A12: 9 | B12: =A12/365 -> 0.024657534 | C12: ='1_Inputs'!$H$3 -> 0.011588203 | D12: =D11*EXP(-'1_Inputs'!$H$3*(1/365)) -> 0.9997143
A13: 10 | B13: =A13/365 -> 0.02739726 | C13: ='1_Inputs'!$H$3 -> 0.011588203 | D13: =D12*EXP(-'1_Inputs'!$H$3*(1/365)) -> 0.99968257
A14: 11 | B14: =A14/365 -> 0.030136986 | C14: ='1_Inputs'!$H$3 -> 0.011588203 | D14: =D13*EXP(-'1_Inputs'!$H$3*(1/365)) -> 0.99965083
A15: 12 | B15: =A15/365 -> 0.032876712 | C15: ='1_Inputs'!$H$3 -> 0.011588203 | D15: =D14*EXP(-'1_Inputs'!$H$3*(1/365)) -> 0.99961909
... A93: 90 | B93: =A93/365 -> 0.24657534 | C93: ='1_Inputs'!$H$3 -> 0.011588203 | D93: =D92*EXP(-'1_Inputs'!$H$3*(1/365)) -> 0.99714671
A94: 91 | B94: =A94/365 -> 0.24931507 | C94: ='1_Inputs'!$H$3 -> 0.011588203 | D94: =D93*EXP(-'1_Inputs'!$H$3*(1/365)) -> 0.99711506 | E94: Quarter end
A95: 92 | B95: =A95/365 -> 0.25205479 | C95: ='1_Inputs'!$H$3 -> 0.011588203 | D95: =D94*EXP(-'1_Inputs'!$H$3*(1/365)) -> 0.9970834
A96: 93 | B96: =A96/365 -> 0.25479452 | C96: ='1_Inputs'!$H$3 -> 0.011588203 | D96: =D95*EXP(-'1_Inputs'!$H$3*(1/365)) -> 0.99705174
A97: 94 | B97: =A97/365 -> 0.25753425 | C97: ='1_Inputs'!$H$3 -> 0.011588203 | D97: =D96*EXP(-'1_Inputs'!$H$3*(1/365)) -> 0.99702009
A98: 95 | B98: =A98/365 -> 0.26027397 | C98: ='1_Inputs'!$H$3 -> 0.011588203 | D98: =D97*EXP(-'1_Inputs'!$H$3*(1/365)) -> 0.99698844
A99: 96 | B99: =A99/365 -> 0.2630137 | C99: ='1_Inputs'!$H$3 -> 0.011588203 | D99: =D98*EXP(-'1_Inputs'!$H$3*(1/365)) -> 0.99695678
A100: 97 | B100: =A100/365 -> 0.26575342 | C100: ='1_Inputs'!$H$3 -> 0.011588203 | D100: =D99*EXP(-'1_Inputs'!$H$3*(1/365)) -> 0.99692513
A101: 98 | B101: =A101/365 -> 0.26849315 | C101: ='1_Inputs'!$H$3 -> 0.011588203 | D101: =D100*EXP(-'1_Inputs'!$H$3*(1/365)) -> 0.99689348
A102: 99 | B102: =A102/365 -> 0.27123288 | C102: ='1_Inputs'!$H$3 -> 0.011588203 | D102: =D101*EXP(-'1_Inputs'!$H$3*(1/365)) -> 0.99686183
A103: 100 | B103: =A103/365 -> 0.2739726 | C103: ='1_Inputs'!$H$3 -> 0.011588203 | D103: =D102*EXP(-'1_Inputs'!$H$3*(1/365)) -> 0.99683018
A104: 101 | B104: =A104/365 -> 0.27671233 | C104: ='1_Inputs'!$H$3 -> 0.011588203 | D104: =D103*EXP(-'1_Inputs'!$H$3*(1/365)) -> 0.99679854
A105: 102 | B105: =A105/365 -> 0.27945205 | C105: ='1_Inputs'!$H$3 -> 0.011588203 | D105: =D104*EXP(-'1_Inputs'!$H$3*(1/365)) -> 0.99676689
A106: 103 | B106: =A106/365 -> 0.28219178 | C106: ='1_Inputs'!$H$3 -> 0.011588203 | D106: =D105*EXP(-'1_Inputs'!$H$3*(1/365)) -> 0.99673525
... A184: 181 | B184: =A184/365 -> 0.49589041 | C184: ='1_Inputs'!$H$3 -> 0.011588203 | D184: =D183*EXP(-'1_Inputs'!$H$3*(1/365)) -> 0.99427
A185: 182 | B185: =A185/365 -> 0.49863014 | C185: ='1_Inputs'!$H$3 -> 0.011588203 | D185: =D184*EXP(-'1_Inputs'!$H$3*(1/365)) -> 0.99423843 | E185: Quarter end
A186: 183 | B186: =A186/365 -> 0.50136986 | C186: ='1_Inputs'!$H$3 -> 0.011588203 | D186: =D185*EXP(-'1_Inputs'!$H$3*(1/365)) -> 0.99420687 | E186: λ changes: 0→6m ends, 6m→1y begins
A187: 184 | B187: =A187/365 -> 0.50410959 | C187: ='1_Inputs'!$H$4 -> 0.010938026 | D187: =D186*EXP(-'1_Inputs'!$H$4*(1/365)) -> 0.99417708
A188: 185 | B188: =A188/365 -> 0.50684932 | C188: ='1_Inputs'!$H$4 -> 0.010938026 | D188: =D187*EXP(-'1_Inputs'!$H$4*(1/365)) -> 0.99414728
A189: 186 | B189: =A189/365 -> 0.50958904 | C189: ='1_Inputs'!$H$4 -> 0.010938026 | D189: =D188*EXP(-'1_Inputs'!$H$4*(1/365)) -> 0.99411749
A190: 187 | B190: =A190/365 -> 0.51232877 | C190: ='1_Inputs'!$H$4 -> 0.010938026 | D190: =D189*EXP(-'1_Inputs'!$H$4*(1/365)) -> 0.9940877
A191: 188 | B191: =A191/365 -> 0.51506849 | C191: ='1_Inputs'!$H$4 -> 0.010938026 | D191: =D190*EXP(-'1_Inputs'!$H$4*(1/365)) -> 0.99405791
A192: 189 | B192: =A192/365 -> 0.51780822 | C192: ='1_Inputs'!$H$4 -> 0.010938026 | D192: =D191*EXP(-'1_Inputs'!$H$4*(1/365)) -> 0.99402812
A193: 190 | B193: =A193/365 -> 0.52054795 | C193: ='1_Inputs'!$H$4 -> 0.010938026 | D193: =D192*EXP(-'1_Inputs'!$H$4*(1/365)) -> 0.99399834
A194: 191 | B194: =A194/365 -> 0.52328767 | C194: ='1_Inputs'!$H$4 -> 0.010938026 | D194: =D193*EXP(-'1_Inputs'!$H$4*(1/365)) -> 0.99396855
...

Sheet 4_Daily_Contributions
A1: DAILY LEG CONTRIBUTIONS — Each row = one calendar day
A2: Day j | B2: t (yrs) | C2: df(mid) | D2: Q(t−1) | E2: Q(t) | F2: dQ=Q(t−1)−Q(t) | G2: Protection contrib | H2: Accrual contrib | I2: Qtr?
A3: 1 | B3: ='2_Discount_Factors'!B4 -> 0.002739726 | C3: =EXP(-r_free*(('2_Discount_Factors'!B3+'2_Discount_Factors'!B4)/2)) -> 0.9999589 | D3: ='3_Survival_Probs'!D3 -> 1 | E3: ='3_Survival_Probs'!D4 -> 0.99996825 | F3: =D3-E3 -> 3.1747998e-05 | G3: =(1-recovery)*notional*C3*F3 -> 190.48016 | H3: =C3*(B3-0)*F3 -> 8.6977243e-08
A4: 2 | B4: ='2_Discount_Factors'!B5 -> 0.0054794521 | C4: =EXP(-r_free*(('2_Discount_Factors'!B4+'2_Discount_Factors'!B5)/2)) -> 0.99987672 | D4: ='3_Survival_Probs'!D4 -> 0.99996825 | E4: ='3_Survival_Probs'!D5 -> 0.99993651 | F4: =D4-E4 -> 3.174699e-05 | G4: =(1-recovery)*notional*C4*F4 -> 190.45846 | H4: =C4*(B4-0)*F4 -> 1.7393467e-07
A5: 3 | B5: ='2_Discount_Factors'!B6 -> 0.0082191781 | C5: =EXP(-r_free*(('2_Discount_Factors'!B5+'2_Discount_Factors'!B6)/2)) -> 0.99979454 | D5: ='3_Survival_Probs'!D5 -> 0.99993651 | E5: ='3_Survival_Probs'!D6 -> 0.99990476 | F5: =D5-E5 -> 3.1745982e-05 | G5: =(1-recovery)*notional*C5*F5 -> 190.43676 | H5: =C5*(B5-0)*F5 -> 2.6087227e-07
A6: 4 | B6: ='2_Discount_Factors'!B7 -> 0.010958904 | C6: =EXP(-r_free*(('2_Discount_Factors'!B6+'2_Discount_Factors'!B7)/2)) -> 0.99971237 | D6: ='3_Survival_Probs'!D6 -> 0.99990476 | E6: ='3_Survival_Probs'!D7 -> 0.99987301 | F6: =D6-E6 -> 3.1744975e-05 | G6: =(1-recovery)*notional*C6*F6 -> 190.41506 | H6: =C6*(B6-0)*F6 -> 3.4779007e-07
A7: 5 | B7: ='2_Discount_Factors'!B8 -> 0.01369863 | C7: =EXP(-r_free*(('2_Discount_Factors'!B7+'2_Discount_Factors'!B8)/2)) -> 0.99963021 | D7: ='3_Survival_Probs'!D7 -> 0.99987301 | E7: ='3_Survival_Probs'!D8 -> 0.99984127 | F7: =D7-E7 -> 3.1743967e-05 | G7: =(1-recovery)*notional*C7*F7 -> 190.39337 | H7: =C7*(B7-0)*F7 -> 4.3468805e-07
A8: 6 | B8: ='2_Discount_Factors'!B9 -> 0.016438356 | C8: =EXP(-r_free*(('2_Discount_Factors'!B8+'2_Discount_Factors'!B9)/2)) -> 0.99954805 | D8: ='3_Survival_Probs'!D8 -> 0.99984127 | E8: ='3_Survival_Probs'!D9 -> 0.99980953 | F8: =D8-E8 -> 3.1742959e-05 | G8: =(1-recovery)*notional*C8*F8 -> 190.37168 | H8: =C8*(B8-0)*F8 -> 5.2156623e-07
A9: 7 | B9: ='2_Discount_Factors'!B10 -> 0.019178082 | C9: =EXP(-r_free*(('2_Discount_Factors'!B9+'2_Discount_Factors'!B10)/2)) -> 0.9994659 | D9: ='3_Survival_Probs'!D9 -> 0.99980953 | E9: ='3_Survival_Probs'!D10 -> 0.99977779 | F9: =D9-E9 -> 3.1741951e-05 | G9: =(1-recovery)*notional*C9*F9 -> 190.34999 | H9: =C9*(B9-0)*F9 -> 6.0842461e-07
A10: 8 | B10: ='2_Discount_Factors'!B11 -> 0.021917808 | C10: =EXP(-r_free*(('2_Discount_Factors'!B10+'2_Discount_Factors'!B11)/2)) -> 0.99938375 | D10: ='3_Survival_Probs'!D10 -> 0.99977779 | E10: ='3_Survival_Probs'!D11 -> 0.99974604 | F10: =D10-E10 -> 3.1740943e-05 | G10: =(1-recovery)*notional*C10*F10 -> 190.3283 | H10: =C10*(B10-0)*F10 -> 6.9526319e-07
A11: 9 | B11: ='2_Discount_Factors'!B12 -> 0.024657534 | C11: =EXP(-r_free*(('2_Discount_Factors'!B11+'2_Discount_Factors'!B12)/2)) -> 0.99930161 | D11: ='3_Survival_Probs'!D11 -> 0.99974604 | E11: ='3_Survival_Probs'!D12 -> 0.9997143 | F11: =D11-E11 -> 3.1739936e-05 | G11: =(1-recovery)*notional*C11*F11 -> 190.30661 | H11: =C11*(B11-0)*F11 -> 7.8208197e-07
A12: 10 | B12: ='2_Discount_Factors'!B13 -> 0.02739726 | C12: =EXP(-r_free*(('2_Discount_Factors'!B12+'2_Discount_Factors'!B13)/2)) -> 0.99921948 | D12: ='3_Survival_Probs'!D12 -> 0.9997143 | E12: ='3_Survival_Probs'!D13 -> 0.99968257 | F12: =D12-E12 -> 3.1738928e-05 | G12: =(1-recovery)*notional*C12*F12 -> 190.28493 | H12: =C12*(B12-0)*F12 -> 8.6888096e-07
A13: 11 | B13: ='2_Discount_Factors'!B14 -> 0.030136986 | C13: =EXP(-r_free*(('2_Discount_Factors'!B13+'2_Discount_Factors'!B14)/2)) -> 0.99913736 | D13: ='3_Survival_Probs'!D13 -> 0.99968257 | E13: ='3_Survival_Probs'!D14 -> 0.99965083 | F13: =D13-E13 -> 3.173792e-05 | G13: =(1-recovery)*notional*C13*F13 -> 190.26325 | H13: =C13*(B13-0)*F13 -> 9.5566017e-07
A14: 12 | B14: ='2_Discount_Factors'!B15 -> 0.032876712 | C14: =EXP(-r_free*(('2_Discount_Factors'!B14+'2_Discount_Factors'!B15)/2)) -> 0.99905524 | D14: ='3_Survival_Probs'!D14 -> 0.99965083 | E14: ='3_Survival_Probs'!D15 -> 0.99961909 | F14: =D14-E14 -> 3.1736913e-05 | G14: =(1-recovery)*notional*C14*F14 -> 190.24157 | H14: =C14*(B14-0)*F14 -> 1.0424196e-06
... A92: 90 | B92: ='2_Discount_Factors'!B93 -> 0.24657534 | C92: =EXP(-r_free*(('2_Discount_Factors'!B92+'2_Discount_Factors'!B93)/2)) -> 0.99267083 | D92: ='3_Survival_Probs'!D92 -> 0.99717837 | E92: ='3_Survival_Probs'!D93 -> 0.99714671 | F92: =D92-E92 -> 3.1658417e-05 | G92: =(1-recovery)*notional*C92*F92 -> 188.55832 | H92: =C92*(B92-0)*F92 -> 7.7489722e-06
A93: 91 | B93: ='2_Discount_Factors'!B94 -> 0.24931507 | C93: =EXP(-r_free*(('2_Discount_Factors'!B93+'2_Discount_Factors'!B94)/2)) -> 0.99258924 | D93: ='3_Survival_Probs'!D93 -> 0.99714671 | E93: ='3_Survival_Probs'!D94 -> 0.99711506 | F93: =D93-E93 -> 3.1657412e-05 | G93: =(1-recovery)*notional*C93*F93 -> 188.53684 | H93: =C93*(B93-0)*F93 -> 7.8341792e-06 | I93: YES
A94: 92 | B94: ='2_Discount_Factors'!B95 -> 0.25205479 | C94: =EXP(-r_free*(('2_Discount_Factors'!B94+'2_Discount_Factors'!B95)/2)) -> 0.99250766 | D94: ='3_Survival_Probs'!D94 -> 0.99711506 | E94: ='3_Survival_Probs'!D95 -> 0.9970834 | F94: =D94-E94 -> 3.1656407e-05 | G94: =(1-recovery)*notional*C94*F94 -> 188.51536 | H94: =C94*(B94-0.249315068493151)*F94 -> 8.6080073e-08
A95: 93 | B95: ='2_Discount_Factors'!B96 -> 0.25479452 | C95: =EXP(-r_free*(('2_Discount_Factors'!B95+'2_Discount_Factors'!B96)/2)) -> 0.99242609 | D95: ='3_Survival_Probs'!D95 -> 0.9970834 | E95: ='3_Survival_Probs'!D96 -> 0.99705174 | F95: =D95-E95 -> 3.1655402e-05 | G95: =(1-recovery)*notional*C95*F95 -> 188.49388 | H95: =C95*(B95-0.249315068493151)*F95 -> 1.7214053e-07
A96: 94 | B96: ='2_Discount_Factors'!B97 -> 0.25753425 | C96: =EXP(-r_free*(('2_Discount_Factors'!B96+'2_Discount_Factors'!B97)/2)) -> 0.99234452 | D96: ='3_Survival_Probs'!D96 -> 0.99705174 | E96: ='3_Survival_Probs'!D97 -> 0.99702009 | F96: =D96-E96 -> 3.1654397e-05 | G96: =(1-recovery)*notional*C96*F96 -> 188.4724 | H96: =C96*(B96-0.249315068493151)*F96 -> 2.5818138e-07
A97: 95 | B97: ='2_Discount_Factors'!B98 -> 0.26027397 | C97: =EXP(-r_free*(('2_Discount_Factors'!B97+'2_Discount_Factors'!B98)/2)) -> 0.99226296 | D97: ='3_Survival_Probs'!D97 -> 0.99702009 | E97: ='3_Survival_Probs'!D98 -> 0.99698844 | F97: =D97-E97 -> 3.1653392e-05 | G97: =(1-recovery)*notional*C97*F97 -> 188.45093 | H97: =C97*(B97-0.249315068493151)*F97 -> 3.4420261e-07
A98: 96 | B98: ='2_Discount_Factors'!B99 -> 0.2630137 | C98: =EXP(-r_free*(('2_Discount_Factors'!B98+'2_Discount_Factors'!B99)/2)) -> 0.99218141 | D98: ='3_Survival_Probs'!D98 -> 0.99698844 | E98: ='3_Survival_Probs'!D99 -> 0.99695678 | F98: =D98-E98 -> 3.1652387e-05 | G98: =(1-recovery)*notional*C98*F98 -> 188.42946 | H98: =C98*(B98-0.249315068493151)*F98 -> 4.3020425e-07
A99: 97 | B99: ='2_Discount_Factors'!B100 -> 0.26575342 | C99: =EXP(-r_free*(('2_Discount_Factors'!B99+'2_Discount_Factors'!B100)/2)) -> 0.99209986 | D99: ='3_Survival_Probs'!D99 -> 0.99695678 | E99: ='3_Survival_Probs'!D100 -> 0.99692513 | F99: =D99-E99 -> 3.1651382e-05 | G99: =(1-recovery)*notional*C99*F99 -> 188.40799 | H99: =C99*(B99-0.249315068493151)*F99 -> 5.1618628e-07
A100: 98 | B100: ='2_Discount_Factors'!B101 -> 0.26849315 | C100: =EXP(-r_free*(('2_Discount_Factors'!B100+'2_Discount_Factors'!B101)/2)) -> 0.99201833 | D100: ='3_Survival_Probs'!D100 -> 0.99692513 | E100: ='3_Survival_Probs'!D101 -> 0.99689348 | F100: =D100-E100 -> 3.1650377e-05 | G100: =(1-recovery)*notional*C100*F100 -> 188.38653 | H100: =C100*(B100-0.249315068493151)*F100 -> 6.0214871e-07
A101: 99 | B101: ='2_Discount_Factors'!B102 -> 0.27123288 | C101: =EXP(-r_free*(('2_Discount_Factors'!B101+'2_Discount_Factors'!B102)/2)) -> 0.99193679 | D101: ='3_Survival_Probs'!D101 -> 0.99689348 | E101: ='3_Survival_Probs'!D102 -> 0.99686183 | F101: =D101-E101 -> 3.1649373e-05 | G101: =(1-recovery)*notional*C101*F101 -> 188.36506 | H101: =C101*(B101-0.249315068493151)*F101 -> 6.8809155e-07
A102: 100 | B102: ='2_Discount_Factors'!B103 -> 0.2739726 | C102: =EXP(-r_free*(('2_Discount_Factors'!B102+'2_Discount_Factors'!B103)/2)) -> 0.99185527 | D102: ='3_Survival_Probs'!D102 -> 0.99686183 | E102: ='3_Survival_Probs'!D103 -> 0.99683018 | F102: =D102-E102 -> 3.1648368e-05 | G102: =(1-recovery)*notional*C102*F102 -> 188.3436 | H102: =C102*(B102-0.249315068493151)*F102 -> 7.740148e-07
A103: 101 | B103: ='2_Discount_Factors'!B104 -> 0.27671233 | C103: =EXP(-r_free*(('2_Discount_Factors'!B103+'2_Discount_Factors'!B104)/2)) -> 0.99177375 | D103: ='3_Survival_Probs'!D103 -> 0.99683018 | E103: ='3_Survival_Probs'!D104 -> 0.99679854 | F103: =D103-E103 -> 3.1647363e-05 | G103: =(1-recovery)*notional*C103*F103 -> 188.32214 | H103: =C103*(B103-0.249315068493151)*F103 -> 8.5991846e-07
A104: 102 | B104: ='2_Discount_Factors'!B105 -> 0.27945205 | C104: =EXP(-r_free*(('2_Discount_Factors'!B104+'2_Discount_Factors'!B105)/2)) -> 0.99169224 | D104: ='3_Survival_Probs'!D104 -> 0.99679854 | E104: ='3_Survival_Probs'!D105 -> 0.99676689 | F104: =D104-E104 -> 3.1646358e-05 | G104: =(1-recovery)*notional*C104*F104 -> 188.30069 | H104: =C104*(B104-0.249315068493151)*F104 -> 9.4580253e-07
A105: 103 | B105: ='2_Discount_Factors'!B106 -> 0.28219178 | C105: =EXP(-r_free*(('2_Discount_Factors'!B105+'2_Discount_Factors'!B106)/2)) -> 0.99161073 | D105: ='3_Survival_Probs'!D105 -> 0.99676689 | E105: ='3_Survival_Probs'!D106 -> 0.99673525 | F105: =D105-E105 -> 3.1645354e-05 | G105: =(1-recovery)*notional*C105*F105 -> 188.27923 | H105: =C105*(B105-0.249315068493151)*F105 -> 1.031667e-06
... A183: 181 | B183: ='2_Discount_Factors'!B184 -> 0.49589041 | C183: =EXP(-r_free*(('2_Discount_Factors'!B183+'2_Discount_Factors'!B184)/2)) -> 0.98527389 | D183: ='3_Survival_Probs'!D183 -> 0.99430157 | E183: ='3_Survival_Probs'!D184 -> 0.99427 | F183: =D183-E183 -> 3.1567084e-05 | G183: =(1-recovery)*notional*C183*F183 -> 186.61334 | H183: =C183*(B183-0.249315068493151)*F183 -> 7.6690415e-06
A184: 182 | B184: ='2_Discount_Factors'!B185 -> 0.49863014 | C184: =EXP(-r_free*(('2_Discount_Factors'!B184+'2_Discount_Factors'!B185)/2)) -> 0.98519291 | D184: ='3_Survival_Probs'!D184 -> 0.99427 | E184: ='3_Survival_Probs'!D185 -> 0.99423843 | F184: =D184-E184 -> 3.1566082e-05 | G184: =(1-recovery)*notional*C184*F184 -> 186.59208 | H184: =C184*(B184-0.249315068493151)*F184 -> 7.7533696e-06 | I184: YES
A185: 183 | B185: ='2_Discount_Factors'!B186 -> 0.50136986 | C185: =EXP(-r_free*(('2_Discount_Factors'!B185+'2_Discount_Factors'!B186)/2)) -> 0.98511194 | D185: ='3_Survival_Probs'!D185 -> 0.99423843 | E185: ='3_Survival_Probs'!D186 -> 0.99420687 | F185: =D185-E185 -> 3.156508e-05 | G185: =(1-recovery)*notional*C185*F185 -> 186.57082 | H185: =C185*(B185-0.498630136986301)*F185 -> 8.5192157e-08
A186: 184 | B186: ='2_Discount_Factors'!B187 -> 0.50410959 | C186: =EXP(-r_free*(('2_Discount_Factors'!B186+'2_Discount_Factors'!B187)/2)) -> 0.98503097 | D186: ='3_Survival_Probs'!D186 -> 0.99420687 | E186: ='3_Survival_Probs'!D187 -> 0.99417708 | F186: =D186-E186 -> 2.9793144e-05 | G186: =(1-recovery)*notional*C186*F186 -> 176.08302 | H186: =C186*(B186-0.498630136986301)*F186 -> 1.6080641e-07
A187: 185 | B187: ='2_Discount_Factors'!B188 -> 0.50684932 | C187: =EXP(-r_free*(('2_Discount_Factors'!B187+'2_Discount_Factors'!B188)/2)) -> 0.98495002 | D187: ='3_Survival_Probs'!D187 -> 0.99417708 | E187: ='3_Survival_Probs'!D188 -> 0.99414728 | F187: =D187-E187 -> 2.9792251e-05 | G187: =(1-recovery)*notional*C187*F187 -> 176.06327 | H187: =C187*(B187-0.498630136986301)*F187 -> 2.4118256e-07
A188: 186 | B188: ='2_Discount_Factors'!B189 -> 0.50958904 | C188: =EXP(-r_free*(('2_Discount_Factors'!B188+'2_Discount_Factors'!B189)/2)) -> 0.98486907 | D188: ='3_Survival_Probs'!D188 -> 0.99414728 | E188: ='3_Survival_Probs'!D189 -> 0.99411749 | F188: =D188-E188 -> 2.9791359e-05 | G188: =(1-recovery)*notional*C188*F188 -> 176.04353 | H188: =C188*(B188-0.498630136986301)*F188 -> 3.2154069e-07
A189: 187 | B189: ='2_Discount_Factors'!B190 -> 0.51232877 | C189: =EXP(-r_free*(('2_Discount_Factors'!B189+'2_Discount_Factors'!B190)/2)) -> 0.98478812 | D189: ='3_Survival_Probs'!D189 -> 0.99411749 | E189: ='3_Survival_Probs'!D190 -> 0.9940877 | F189: =D189-E189 -> 2.9790466e-05 | G189: =(1-recovery)*notional*C189*F189 -> 176.02378 | H189: =C189*(B189-0.498630136986301)*F189 -> 4.0188078e-07
A190: 188 | B190: ='2_Discount_Factors'!B191 -> 0.51506849 | C190: =EXP(-r_free*(('2_Discount_Factors'!B190+'2_Discount_Factors'!B191)/2)) -> 0.98470718 | D190: ='3_Survival_Probs'!D190 -> 0.9940877 | E190: ='3_Survival_Probs'!D191 -> 0.99405791 | F190: =D190-E190 -> 2.9789573e-05 | G190: =(1-recovery)*notional*C190*F190 -> 176.00404 | H190: =C190*(B190-0.498630136986301)*F190 -> 4.8220285e-07
A191: 189 | B191: ='2_Discount_Factors'!B192 -> 0.51780822 | C191: =EXP(-r_free*(('2_Discount_Factors'!B191+'2_Discount_Factors'!B192)/2)) -> 0.98462625 | D191: ='3_Survival_Probs'!D191 -> 0.99405791 | E191: ='3_Survival_Probs'!D192 -> 0.99402812 | F191: =D191-E191 -> 2.9788681e-05 | G191: =(1-recovery)*notional*C191*F191 -> 175.9843 | H191: =C191*(B191-0.498630136986301)*F191 -> 5.625069e-07
A192: 190 | B192: ='2_Discount_Factors'!B193 -> 0.52054795 | C192: =EXP(-r_free*(('2_Discount_Factors'!B192+'2_Discount_Factors'!B193)/2)) -> 0.98454533 | D192: ='3_Survival_Probs'!D192 -> 0.99402812 | E192: ='3_Survival_Probs'!D193 -> 0.99399834 | F192: =D192-E192 -> 2.9787788e-05 | G192: =(1-recovery)*notional*C192*F192 -> 175.96456 | H192: =C192*(B192-0.498630136986301)*F192 -> 6.4279293e-07
A193: 191 | B193: ='2_Discount_Factors'!B194 -> 0.52328767 | C193: =EXP(-r_free*(('2_Discount_Factors'!B193+'2_Discount_Factors'!B194)/2)) -> 0.98446441 | D193: ='3_Survival_Probs'!D193 -> 0.99399834 | E193: ='3_Survival_Probs'!D194 -> 0.99396855 | F193: =D193-E193 -> 2.9786895e-05 | G193: =(1-recovery)*notional*C193*F193 -> 175.94483 | H193: =C193*(B193-0.498630136986301)*F193 -> 7.2306094e-07
A194: 192 | B194: ='2_Discount_Factors'!B195 -> 0.5260274 | C194: =EXP(-r_free*(('2_Discount_Factors'!B194+'2_Discount_Factors'!B195)/2)) -> 0.9843835 | D194: ='3_Survival_Probs'!D194 -> 0.99396855 | E194: ='3_Survival_Probs'!D195 -> 0.99393876 | F194: =D194-E194 -> 2.9786003e-05 | G194: =(1-recovery)*notional*C194*F194 -> 175.9251 | H194: =C194*(B194-0.498630136986301)*F194 -> 8.0331094e-07
...

Sheet 5_Pricing_Summary
A1: CDS PRICING SUMMARY — All values via Excel formulas from Sheets 2-4
A2: Tenor | B2: Protection Leg ($) | C2: Model Spread(bps) | D2: Mkt Spread(bps) | E2: Error(bps) | F2: RPV01(yrs) | G2: CS01($) | H2: Q(end)
A3: 6m | B3: =SUM('4_Daily_Contributions'!G3:G185) -> 34498.936 | C3: =B3/(F3*notional)*10000 -> 69.999913 | D3: ='1_Inputs'!E3 -> 70 | E3: =C3-D3 -> -8.6564966e-05 | F3: =(0.25*'3_Survival_Probs'!D97*'2_Discount_Factors'!C97+0.25*'3_Survival_Probs'!D188*'2_Discount_Factors'!C188)+SUM('4_Daily_Contributions'!H3:H185) -> 0.49284255 | G3: =F3*notional/10000 -> 492.84255 | H3: ='3_Survival_Probs'!D186 -> 0.99420687
A4: 1y | B4: =SUM('4_Daily_Contributions'!G3:G367) -> 66222.951 | C4: =B4/(F4*notional)*10000 -> 89.999383 | D4: ='1_Inputs'!E4 -> 90 | E4: =C4-D4 -> -0.00061691767 | F4: =(0.25*'3_Survival_Probs'!D97*'2_Discount_Factors'!C97+0.25*'3_Survival_Probs'!D188*'2_Discount_Factors'!C188+0.25*'3_Survival_Probs'!D279*'2_Discount_Factors'!C279)+SUM('4_Daily_Contributions'!H3:H367) -> 0.73581561 | G4: =F4*notional/10000 -> 735.81561 | H4: ='3_Survival_Probs'!D368 -> 0.9887992
A5: 2y | B5: =SUM('4_Daily_Contributions'!G3:G732) -> 184735.5 | C5: =B5/(F5*notional)*10000 -> 110 | D5: ='1_Inputs'!E5 -> 110 | E5: =C5-D5 -> -1.5704804e-06 | F5: =(0.25*'3_Survival_Probs'!D97*'2_Discount_Factors'!C97+0.25*'3_Survival_Probs'!D188*'2_Discount_Factors'!C188+0.25*'3_Survival_Probs'!D279*'2_Discount_Factors'!C279+0.25*'3_Survival_Probs'!D371*'2_Discount_Factors'!C371+0.25*'3_Survival_Probs'!D462*'2_Discount_Factors'!C462+0.25*'3_Survival_Probs'!D553*'2_Discount_Factors'!C553+0.25*'3_Survival_Probs'!D644*'2_Discount_Factors'!C644)+SUM('4_Daily_Contributions'!H3:H732) -> 1.6794136 | G5: =F5*notional/10000 -> 1679.4136 | H5: ='3_Survival_Probs'!D733 -> 0.96813982
A6: 3y | B6: =SUM('4_Daily_Contributions'!G3:G1097) -> 334669.35 | C6: =B6/(F6*notional)*10000 -> 130 | D6: ='1_Inputs'!E6 -> 130 | E6: =C6-D6 -> -2.9603178e-06 | F6: =(0.25*'3_Survival_Probs'!D97*'2_Discount_Factors'!C97+0.25*'3_Survival_Probs'!D188*'2_Discount_Factors'!C188+0.25*'3_Survival_Probs'!D279*'2_Discount_Factors'!C279+0.25*'3_Survival_Probs'!D371*'2_Discount_Factors'!C371+0.25*'3_Survival_Probs'!D462*'2_Discount_Factors'!C462+0.25*'3_Survival_Probs'!D553*'2_Discount_Factors'!C553+0.25*'3_Survival_Probs'!D644*'2_Discount_Factors'!C644+0.25*'3_Survival_Probs'!D736*'2_Discount_Factors'!C736+0.25*'3_Survival_Probs'!D827*'2_Discount_Factors'!C827+0.25*'3_Survival_Probs'!D918*'2_Discount_Factors'!C918+0.25*'3_Survival_Probs'!D1009*'2_Discount_Factors'!C1009)+SUM('4_Daily_Contributions'!H3:H1097) -> 2.5743796 | G6: =F6*notional/10000 -> 2574.3796 | H6: ='3_Survival_Probs'!D1098 -> 0.94120751
A7: 5y | B7: =SUM('4_Daily_Contributions'!G3:G1827) -> 631872.59 | C7: =B7/(F7*notional)*10000 -> 149.99998 | D7: ='1_Inputs'!E7 -> 150 | E7: =C7-D7 -> -1.8140978e-05 | F7: =(0.25*'3_Survival_Probs'!D97*'2_Discount_Factors'!C97+0.25*'3_Survival_Probs'!D188*'2_Discount_Factors'!C188+0.25*'3_Survival_Probs'!D279*'2_Discount_Factors'!C279+0.25*'3_Survival_Probs'!D371*'2_Discount_Factors'!C371+0.25*'3_Survival_Probs'!D462*'2_Discount_Factors'!C462+0.25*'3_Survival_Probs'!D553*'2_Discount_Factors'!C553+0.25*'3_Survival_Probs'!D644*'2_Discount_Factors'!C644+0.25*'3_Survival_Probs'!D736*'2_Discount_Factors'!C736+0.25*'3_Survival_Probs'!D827*'2_Discount_Factors'!C827+0.25*'3_Survival_Probs'!D918*'2_Discount_Factors'!C918+0.25*'3_Survival_Probs'!D1009*'2_Discount_Factors'!C1009+0.25*'3_Survival_Probs'!D1101*'2_Discount_Factors'!C1101+0.25*'3_Survival_Probs'!D1192*'2_Discount_Factors'!C1192+0.25*'3_Survival_Probs'!D1283*'2_Discount_Factors'!C1283+0.25*'3_Survival_Probs'!D1374*'2_Discount_Factors'!C1374+0.25*'3_Survival_Probs'!D1466*'2_Discount_Factors'!C1466+0.25*'3_Survival_Probs'!D1557*'2_Discount_Factors'!C1557+0.25*'3_Survival_Probs'!D1648*'2_Discount_Factors'!C1648+0.25*'3_Survival_Probs'!D1739*'2_Discount_Factors'!C1739)+SUM('4_Daily_Contributions'!H3:H1827) -> 4.2124844 | G7: =F7*notional/10000 -> 4212.4844 | H7: ='3_Survival_Probs'!D1828 -> 0.88538367
A9: Protection Leg = SUM of daily contributions from Sheet 4. RPV01 = quarterly premium sum × Q(t) × df(t) + accrual sum. Model Spread = Protection Leg / (RPV01 × N) × 10000 in bps. Error should be <0.001bps when λ values are correctly calibrated. If error is large: use Solver on Sheet 1 to recalibrate λ.

Sheet 6_Curve_Summary
A1: SURVIVAL & HAZARD RATE CURVE — Key Dates Summary
A2: Tenor | B2: Day | C2: t (yrs) | D2: Q(t) | E2: Cum Def Prob | F2: λ applicable
A3: 3m | B3: 91 | C3: ='3_Survival_Probs'!B94 -> 0.24931507 | D3: ='3_Survival_Probs'!D94 -> 0.99711506 | E3: =1-D3 -> 0.0028849442 | F3: ='3_Survival_Probs'!C94 -> 0.011588203
A4: 6m | B4: 182 | C4: ='3_Survival_Probs'!B185 -> 0.49863014 | D4: ='3_Survival_Probs'!D185 -> 0.99423843 | E4: =1-D4 -> 0.0057615656 | F4: ='3_Survival_Probs'!C185 -> 0.011588203
A5: 9m | B5: 273 | C5: ='3_Survival_Probs'!B276 -> 0.74794521 | D5: ='3_Survival_Probs'!D276 -> 0.99152906 | E5: =1-D5 -> 0.0084709411 | F5: ='3_Survival_Probs'!C276 -> 0.010938026
A6: 1y | B6: 365 | C6: ='3_Survival_Probs'!B368 -> 1 | D6: ='3_Survival_Probs'!D368 -> 0.9887992 | E6: =1-D6 -> 0.011200804 | F6: ='3_Survival_Probs'!C368 -> 0.010938026
A7: 18m | B7: 547 | C7: ='3_Survival_Probs'!B550 -> 1.4986301 | D7: ='3_Survival_Probs'!D550 -> 0.97844328 | E7: =1-D7 -> 0.021556716 | F7: ='3_Survival_Probs'!C550 -> 0.02111475
A8: 2y | B8: 730 | C8: ='3_Survival_Probs'!B733 -> 2 | D8: ='3_Survival_Probs'!D733 -> 0.96813982 | E8: =1-D8 -> 0.031860176 | F8: ='3_Survival_Probs'!C733 -> 0.02111475
A9: 3y | B9: 1095 | C9: ='3_Survival_Probs'!B1098 -> 3 | D9: ='3_Survival_Probs'!D1098 -> 0.94120751 | E9: =1-D9 -> 0.058792487 | F9: ='3_Survival_Probs'!C1098 -> 0.028212884
A10: 4y | B10: 1460 | C10: ='3_Survival_Probs'!B1463 -> 4 | D10: ='3_Survival_Probs'!D1463 -> 0.91286897 | E10: =1-D10 -> 0.087131028 | F10: ='3_Survival_Probs'!C1463 -> 0.030571282
A11: 5y | B11: 1825 | C11: ='3_Survival_Probs'!B1828 -> 5 | D11: ='3_Survival_Probs'!D1828 -> 0.88538367 | E11: =1-D11 -> 0.11461633 | F11: ='3_Survival_Probs'!C1828 -> 0.030571282
A14: HAZARD RATE CURVE
A15: Segment | B15: λ (decimal) | C15: λ (bps) | D15: Mkt Spread(bps) | E15: Approx S=λ×(1−R) | F15: Q at segment end
A16: 0→6m | B16: ='1_Inputs'!H3 -> 0.011588203 | C16: =B16*10000 -> 115.88203 | D16: ='1_Inputs'!E3 -> 70 | E16: =B16*(1-recovery)*10000 -> 69.52922 | F16: ='3_Survival_Probs'!D186 -> 0.99420687
A17: 6m→1y | B17: ='1_Inputs'!H4 -> 0.010938026 | C17: =B17*10000 -> 109.38026 | D17: ='1_Inputs'!E4 -> 90 | E17: =B17*(1-recovery)*10000 -> 65.628156 | F17: ='3_Survival_Probs'!D368 -> 0.9887992
A18: 1→2y | B18: ='1_Inputs'!H5 -> 0.02111475 | C18: =B18*10000 -> 211.1475 | D18: ='1_Inputs'!E5 -> 110 | E18: =B18*(1-recovery)*10000 -> 126.6885 | F18: ='3_Survival_Probs'!D733 -> 0.96813982
A19: 2→3y | B19: ='1_Inputs'!H6 -> 0.028212884 | C19: =B19*10000 -> 282.12884 | D19: ='1_Inputs'!E6 -> 130 | E19: =B19*(1-recovery)*10000 -> 169.2773 | F19: ='3_Survival_Probs'!D1098 -> 0.94120751
A20: 3→5y | B20: ='1_Inputs'!H7 -> 0.030571282 | C20: =B20*10000 -> 305.71282 | D20: ='1_Inputs'!E7 -> 150 | E20: =B20*(1-recovery)*10000 -> 183.42769 | F20: ='3_Survival_Probs'!D1828 -> 0.88538367
A22: CHART DATA
A23: Tenor | B23: Q(t) | C23: Cum Def Prob(%)
A24: 0 | B24: 1 | C24: 0
A25: 3m | B25: ='3_Survival_Probs'!D94 -> 0.99711506 | C25: =(1-B25)*100 -> 0.28849442
A26: 6m | B26: ='3_Survival_Probs'!D185 -> 0.99423843 | C26: =(1-B26)*100 -> 0.57615656
A27: 1y | B27: ='3_Survival_Probs'!D368 -> 0.9887992 | C27: =(1-B27)*100 -> 1.1200804
A28: 2y | B28: ='3_Survival_Probs'!D733 -> 0.96813982 | C28: =(1-B28)*100 -> 3.1860176
A29: 3y | B29: ='3_Survival_Probs'!D1098 -> 0.94120751 | C29: =(1-B29)*100 -> 5.8792487
A30: 4y | B30: ='3_Survival_Probs'!D1463 -> 0.91286897 | C30: =(1-B30)*100 -> 8.7131028
A31: 5y | B31: ='3_Survival_Probs'!D1828 -> 0.88538367 | C31: =(1-B31)*100 -> 11.461633
