Workbook

Sheet Instruments
B1: Market Instruments · All input cells (blue) — do not modify
B3: OIS MONEY MARKET (Simple Interest, Act/360)
B4: Instrument | C4: Tenor | D4: Rate | E4: Description
B5: 3M SOFR | C5: 0.25 | D5: 0.0415
B6: 6M SOFR | C6: 0.5 | D6: 0.04
B7: OIS SWAPS (Annual Fixed vs Daily Compounded SOFR)
B8: Instrument | C8: Tenor | D8: Par Rate | E8: Description
B9: 1Y OIS | C9: 1 | D9: 0.038
B10: 2Y OIS | C10: 2 | D10: 0.037
B11: 3Y OIS | C11: 3 | D11: 0.0365
B12: 5Y OIS | C12: 5 | D12: 0.036
B13: 7Y OIS | C13: 7 | D13: 0.0358
B14: 10Y OIS | C14: 10 | D14: 0.0355
B17: SOFR FUTURES (Implies 3M SOFR forward rate per quarterly period)
B18: Contract | C18: T_start | D18: T_end | E18: Implied 3M Fwd | F18: Description
B19: Sep25 | C19: 0 | D19: 0.25 | E19: 0.044 | F19: 3M SOFR for Sep25
B20: Dec25 | C20: 0.25 | D20: 0.5 | E20: 0.0425 | F20: 3M SOFR for Dec25
B21: Mar26 | C21: 0.5 | D21: 0.75 | E21: 0.0408 | F21: 3M SOFR for Mar26
B22: Jun26 | C22: 0.75 | D22: 1 | E22: 0.0392 | F22: 3M SOFR for Jun26
B23: Sep26 | C23: 1 | D23: 1.25 | E23: 0.0382 | F23: 3M SOFR for Sep26
B24: Dec26 | C24: 1.25 | D24: 1.5 | E24: 0.0376 | F24: 3M SOFR for Dec26
B25: Mar27 | C25: 1.5 | D25: 1.75 | E25: 0.0372 | F25: 3M SOFR for Mar27
B26: Jun27 | C26: 1.75 | D26: 2 | E26: 0.037 | F26: 3M SOFR for Jun27
B27: 3M SOFR IRS (Quarterly Float vs Annual Fixed, used for 2Y+ projection curve)
B28: Instrument | C28: Tenor | D28: Par Rate | E28: Description
B29: 2Y SOFR IRS | C29: 2 | D29: 0.0371 | E29: 3M SOFR IRS 2Y par rate — used to bootstrap projection fwds beyond 2Y
B30: 3Y SOFR IRS | C30: 3 | D30: 0.0367 | E30: 3M SOFR IRS 3Y par rate — used to bootstrap projection fwds beyond 2Y
B31: 5Y SOFR IRS | C31: 5 | D31: 0.0364 | E31: 3M SOFR IRS 5Y par rate — used to bootstrap projection fwds beyond 2Y
B32: 7Y SOFR IRS | C32: 7 | D32: 0.0362 | E32: 3M SOFR IRS 7Y par rate — used to bootstrap projection fwds beyond 2Y
B33: 10Y SOFR IRS | C33: 10 | D33: 0.0359 | E33: 3M SOFR IRS 10Y par rate — used to bootstrap projection fwds beyond 2Y

Sheet OIS_Curve
B1: OIS Curve · Bootstrap → Discount Factors → Zero Rates → Quarterly Grid
B3: SECTION 1 — SEQUENTIAL OIS BOOTSTRAP (liquid & interpolated tenors)
B4: Tenor | C4: Type | D4: Instr Rate | E4: Discount Factor | F4: Zero Rate (cont) | G4: Formula / Note
B5: 0.25 | C5: MM | D5: =Instruments!$D$5 -> 0.0415 | E5: =1/(1+D5*B5) -> 0.98973154 | F5: =-LN(E5)/B5 -> 0.041286196 | G5: P = 1/(1+r·T) [simple interest, T=0.25]
B6: 0.5 | C6: MM | D6: =Instruments!$D$6 -> 0.04 | E6: =1/(1+D6*B6) -> 0.98039216 | F6: =-LN(E6)/B6 -> 0.039605255 | G6: P = 1/(1+r·T) [simple interest, T=0.50]
B7: 1 | C7: OIS Swap | D7: =Instruments!$D$9 -> 0.038 | E7: =1/(1+D7) -> 0.96339114 | F7: =-LN(E7)/B7 -> 0.037295785 | G7: P = 1/(1+S) [1Y swap: single payment, P(1)=1/(1+S)]
B8: 2 | C8: OIS Swap | D8: =Instruments!$D$10 -> 0.037 | E8: =(1-D8*E7)/(1+D8) -> 0.92994651 | F8: =-LN(E8)/B8 -> 0.036314107 | G8: P = (1-S·P1)/(1+S) [2Y bootstrap]
B9: 3 | C9: OIS Swap | D9: =Instruments!$D$11 -> 0.0365 | E9: =(1-D9*(E7+E8))/(1+D9) -> 0.89811208 | F9: =-LN(E9)/B9 -> 0.035820134 | G9: P = (1-S·(P1+P2))/(1+S) [3Y bootstrap]
B10: 4 | C10: Interp | D10: — | E10: =EXP(-F10*B10) -> 0.86619929 | F10: =F9+(Instruments!$D$12-F9)*(B10-B9)/(5-B9) -> 0.035910067 | G10: INTERP: z4 = z3 + (S5Y-z3)·(4-3)/(5-3) → P4 = EXP(-z4·4) [uses S5Y as proxy for z5]
B11: 5 | C11: OIS Swap | D11: =Instruments!$D$12 -> 0.036 | E11: =(1-D11*(E7+E8+E9+E10))/(1+D11) -> 0.83815119 | F11: =-LN(E11)/B11 -> 0.035311355 | G11: P = (1-S·(P1+P2+P3+P4))/(1+S) [5Y bootstrap using interpolated P4]
B12: 6 | C12: Interp | D12: — | E12: =EXP(-F12*B12) -> 0.80788621 | F12: =F11+(Instruments!$D$13-F11)*(B12-B11)/(7-B11) -> 0.035555677 | G12: INTERP: z6 = z5 + (S7Y-z5)·(6-5)/(7-5) → P6 = EXP(-z6·6)
B13: 7 | C13: OIS Swap | D13: =Instruments!$D$13 -> 0.0358 | E13: =(1-D13*(E7+E8+E9+E10+E11+E12))/(1+D13) -> 0.78212785 | F13: =-LN(E13)/B13 -> 0.035105295 | G13: P = (1-S·(P1+...+P6))/(1+S) [7Y bootstrap]
B14: 8 | C14: Interp | D14: — | E14: =EXP(-F14*B14) -> 0.75435296 | F14: =F13+(Instruments!$D$14-F13)*(B14-B13)/(10-B13) -> 0.035236863 | G14: INTERP: z8 = z7 + (S10Y-z7)·(8-7)/(10-7) → P8 = EXP(-z8·8)
B15: 9 | C15: Interp | D15: — | E15: =EXP(-F15*B15) -> 0.72737299 | F15: =F13+(Instruments!$D$14-F13)*(B15-B13)/(10-B13) -> 0.035368432 | G15: INTERP: z9 = z7 + (S10Y-z7)·(9-7)/(10-7) → P9 = EXP(-z9·9)
B16: 10 | C16: OIS Swap | D16: =Instruments!$D$14 -> 0.0355 | E16: =(1-D16*(E7+E8+E9+E10+E11+E12+E13+E14+E15))/(1+D16) -> 0.7062794 | F16: =-LN(E16)/B16 -> 0.034774436 | G16: P = (1-S·(P1+...+P9))/(1+S) [10Y bootstrap]
B17: SECTION 2 — QUARTERLY OUTPUT GRID (piecewise linear interp on zero rates)
B18: Tenor | C18: Zero Rate (interp) | D18: Discount Factor | E18: Inst. Fwd Rate | F18: 3M OIS Fwd | G18: Formula Key
B19: 0.25 | C19: =INDEX($F$5:$F$16,MIN(MATCH(B19,$B$5:$B$16,1),11))+(INDEX($F$5:$F$16,MIN(MATCH(B19,$B$5:$B$16,1),11)+1)-INDEX($F$5:$F$16,MIN(MATCH(B19,$B$5:$B$16,1),11)))/(INDEX($B$5:$B$16,MIN(MATCH(B19,$B$5:$B$16,1),11)+1)-INDEX($B$5:$B$16,MIN(MATCH(B19,$B$5:$B$16,1),11)))*(B19-INDEX($B$5:$B$16,MIN(MATCH(B19,$B$5:$B$16,1),11))) -> 0.041286196 | D19: =EXP(-C19*B19) -> 0.98973154 | E19: =-LN(D19)/B19 -> 0.041286196 | F19: =(D19/D20-1)/0.25 -> 0.038104664 | G19: Z=MATCH+INDEX linear interp | DF=EXP(-Z·T) | IF=central diff | 3Mfwd=(DF/DF+1-1)/0.25
B20: 0.5 | C20: =INDEX($F$5:$F$16,MIN(MATCH(B20,$B$5:$B$16,1),11))+(INDEX($F$5:$F$16,MIN(MATCH(B20,$B$5:$B$16,1),11)+1)-INDEX($F$5:$F$16,MIN(MATCH(B20,$B$5:$B$16,1),11)))/(INDEX($B$5:$B$16,MIN(MATCH(B20,$B$5:$B$16,1),11)+1)-INDEX($B$5:$B$16,MIN(MATCH(B20,$B$5:$B$16,1),11)))*(B20-INDEX($B$5:$B$16,MIN(MATCH(B20,$B$5:$B$16,1),11))) -> 0.039605255 | D20: =EXP(-C20*B20) -> 0.98039216 | E20: =(LN(D19)-LN(D21))/(B21-B19) -> 0.037032681 | F20: =(D20/D21-1)/0.25 -> 0.036304815 | G20: Z=MATCH+INDEX linear interp | DF=EXP(-Z·T) | IF=central diff | 3Mfwd=(DF/DF+1-1)/0.25
B21: 0.75 | C21: =INDEX($F$5:$F$16,MIN(MATCH(B21,$B$5:$B$16,1),11))+(INDEX($F$5:$F$16,MIN(MATCH(B21,$B$5:$B$16,1),11)+1)-INDEX($F$5:$F$16,MIN(MATCH(B21,$B$5:$B$16,1),11)))/(INDEX($B$5:$B$16,MIN(MATCH(B21,$B$5:$B$16,1),11)+1)-INDEX($B$5:$B$16,MIN(MATCH(B21,$B$5:$B$16,1),11)))*(B21-INDEX($B$5:$B$16,MIN(MATCH(B21,$B$5:$B$16,1),11))) -> 0.03845052 | D21: =EXP(-C21*B21) -> 0.97157395 | E21: =(LN(D20)-LN(D22))/(B22-B20) -> 0.034986315 | F21: =(D21/D22-1)/0.25 -> 0.033975056 | G21: Z=MATCH+INDEX linear interp | DF=EXP(-Z·T) | IF=central diff | 3Mfwd=(DF/DF+1-1)/0.25
B22: 1 | C22: =INDEX($F$5:$F$16,MIN(MATCH(B22,$B$5:$B$16,1),11))+(INDEX($F$5:$F$16,MIN(MATCH(B22,$B$5:$B$16,1),11)+1)-INDEX($F$5:$F$16,MIN(MATCH(B22,$B$5:$B$16,1),11)))/(INDEX($B$5:$B$16,MIN(MATCH(B22,$B$5:$B$16,1),11)+1)-INDEX($B$5:$B$16,MIN(MATCH(B22,$B$5:$B$16,1),11)))*(B22-INDEX($B$5:$B$16,MIN(MATCH(B22,$B$5:$B$16,1),11))) -> 0.037295785 | D22: =EXP(-C22*B22) -> 0.96339114 | E22: =(LN(D21)-LN(D23))/(B23-B21) -> 0.034950134 | F22: =(D22/D23-1)/0.25 -> 0.036231796
B23: 1.25 | C23: =INDEX($F$5:$F$16,MIN(MATCH(B23,$B$5:$B$16,1),11))+(INDEX($F$5:$F$16,MIN(MATCH(B23,$B$5:$B$16,1),11)+1)-INDEX($F$5:$F$16,MIN(MATCH(B23,$B$5:$B$16,1),11)))/(INDEX($B$5:$B$16,MIN(MATCH(B23,$B$5:$B$16,1),11)+1)-INDEX($B$5:$B$16,MIN(MATCH(B23,$B$5:$B$16,1),11)))*(B23-INDEX($B$5:$B$16,MIN(MATCH(B23,$B$5:$B$16,1),11))) -> 0.037050365 | D23: =EXP(-C23*B23) -> 0.95474312 | E23: =(LN(D22)-LN(D24))/(B24-B22) -> 0.035823268 | F23: =(D23/D24-1)/0.25 -> 0.035736541
B24: 1.5 | C24: =INDEX($F$5:$F$16,MIN(MATCH(B24,$B$5:$B$16,1),11))+(INDEX($F$5:$F$16,MIN(MATCH(B24,$B$5:$B$16,1),11)+1)-INDEX($F$5:$F$16,MIN(MATCH(B24,$B$5:$B$16,1),11)))/(INDEX($B$5:$B$16,MIN(MATCH(B24,$B$5:$B$16,1),11)+1)-INDEX($B$5:$B$16,MIN(MATCH(B24,$B$5:$B$16,1),11)))*(B24-INDEX($B$5:$B$16,MIN(MATCH(B24,$B$5:$B$16,1),11))) -> 0.036804946 | D24: =EXP(-C24*B24) -> 0.94628885 | E24: =(LN(D23)-LN(D25))/(B25-B23) -> 0.035332429 | F24: =(D24/D25-1)/0.25 -> 0.035241348
B25: 1.75 | C25: =INDEX($F$5:$F$16,MIN(MATCH(B25,$B$5:$B$16,1),11))+(INDEX($F$5:$F$16,MIN(MATCH(B25,$B$5:$B$16,1),11)+1)-INDEX($F$5:$F$16,MIN(MATCH(B25,$B$5:$B$16,1),11)))/(INDEX($B$5:$B$16,MIN(MATCH(B25,$B$5:$B$16,1),11)+1)-INDEX($B$5:$B$16,MIN(MATCH(B25,$B$5:$B$16,1),11)))*(B25-INDEX($B$5:$B$16,MIN(MATCH(B25,$B$5:$B$16,1),11))) -> 0.036559526 | D25: =EXP(-C25*B25) -> 0.93802454 | E25: =(LN(D24)-LN(D26))/(B26-B24) -> 0.03484159 | F25: =(D25/D26-1)/0.25 -> 0.034746215
B26: 2 | C26: =INDEX($F$5:$F$16,MIN(MATCH(B26,$B$5:$B$16,1),11))+(INDEX($F$5:$F$16,MIN(MATCH(B26,$B$5:$B$16,1),11)+1)-INDEX($F$5:$F$16,MIN(MATCH(B26,$B$5:$B$16,1),11)))/(INDEX($B$5:$B$16,MIN(MATCH(B26,$B$5:$B$16,1),11)+1)-INDEX($B$5:$B$16,MIN(MATCH(B26,$B$5:$B$16,1),11)))*(B26-INDEX($B$5:$B$16,MIN(MATCH(B26,$B$5:$B$16,1),11))) -> 0.036314107 | D26: =EXP(-C26*B26) -> 0.92994651 | E26: =(LN(D25)-LN(D27))/(B27-B25) -> 0.034899419 | F26: =(D26/D27-1)/0.25 -> 0.035358027
B27: 2.25 | C27: =INDEX($F$5:$F$16,MIN(MATCH(B27,$B$5:$B$16,1),11))+(INDEX($F$5:$F$16,MIN(MATCH(B27,$B$5:$B$16,1),11)+1)-INDEX($F$5:$F$16,MIN(MATCH(B27,$B$5:$B$16,1),11)))/(INDEX($B$5:$B$16,MIN(MATCH(B27,$B$5:$B$16,1),11)+1)-INDEX($B$5:$B$16,MIN(MATCH(B27,$B$5:$B$16,1),11)))*(B27-INDEX($B$5:$B$16,MIN(MATCH(B27,$B$5:$B$16,1),11))) -> 0.036190614 | D27: =EXP(-C27*B27) -> 0.92179827 | E27: =(LN(D26)-LN(D28))/(B28-B26) -> 0.035079175 | F27: =(D27/D28-1)/0.25 -> 0.035108865
B28: 2.5 | C28: =INDEX($F$5:$F$16,MIN(MATCH(B28,$B$5:$B$16,1),11))+(INDEX($F$5:$F$16,MIN(MATCH(B28,$B$5:$B$16,1),11)+1)-INDEX($F$5:$F$16,MIN(MATCH(B28,$B$5:$B$16,1),11)))/(INDEX($B$5:$B$16,MIN(MATCH(B28,$B$5:$B$16,1),11)+1)-INDEX($B$5:$B$16,MIN(MATCH(B28,$B$5:$B$16,1),11)))*(B28-INDEX($B$5:$B$16,MIN(MATCH(B28,$B$5:$B$16,1),11))) -> 0.03606712 | D28: =EXP(-C28*B28) -> 0.91377784 | E28: =(LN(D27)-LN(D29))/(B29-B27) -> 0.034832189 | F28: =(D28/D29-1)/0.25 -> 0.034859719
B29: 2.75 | C29: =INDEX($F$5:$F$16,MIN(MATCH(B29,$B$5:$B$16,1),11))+(INDEX($F$5:$F$16,MIN(MATCH(B29,$B$5:$B$16,1),11)+1)-INDEX($F$5:$F$16,MIN(MATCH(B29,$B$5:$B$16,1),11)))/(INDEX($B$5:$B$16,MIN(MATCH(B29,$B$5:$B$16,1),11)+1)-INDEX($B$5:$B$16,MIN(MATCH(B29,$B$5:$B$16,1),11)))*(B29-INDEX($B$5:$B$16,MIN(MATCH(B29,$B$5:$B$16,1),11))) -> 0.035943627 | D29: =EXP(-C29*B29) -> 0.90588313 | E29: =(LN(D28)-LN(D30))/(B30-B28) -> 0.034585202 | F29: =(D29/D30-1)/0.25 -> 0.034610588
B30: 3 | C30: =INDEX($F$5:$F$16,MIN(MATCH(B30,$B$5:$B$16,1),11))+(INDEX($F$5:$F$16,MIN(MATCH(B30,$B$5:$B$16,1),11)+1)-INDEX($F$5:$F$16,MIN(MATCH(B30,$B$5:$B$16,1),11)))/(INDEX($B$5:$B$16,MIN(MATCH(B30,$B$5:$B$16,1),11)+1)-INDEX($B$5:$B$16,MIN(MATCH(B30,$B$5:$B$16,1),11)))*(B30-INDEX($B$5:$B$16,MIN(MATCH(B30,$B$5:$B$16,1),11))) -> 0.035820134 | D30: =EXP(-C30*B30) -> 0.89811208 | E30: =(LN(D29)-LN(D31))/(B31-B29) -> 0.035287063 | F30: =(D30/D31-1)/0.25 -> 0.036275921
B31: 3.25 | C31: =INDEX($F$5:$F$16,MIN(MATCH(B31,$B$5:$B$16,1),11))+(INDEX($F$5:$F$16,MIN(MATCH(B31,$B$5:$B$16,1),11)+1)-INDEX($F$5:$F$16,MIN(MATCH(B31,$B$5:$B$16,1),11)))/(INDEX($B$5:$B$16,MIN(MATCH(B31,$B$5:$B$16,1),11)+1)-INDEX($B$5:$B$16,MIN(MATCH(B31,$B$5:$B$16,1),11)))*(B31-INDEX($B$5:$B$16,MIN(MATCH(B31,$B$5:$B$16,1),11))) -> 0.035842617 | D31: =EXP(-C31*B31) -> 0.89004033 | E31: =(LN(D30)-LN(D32))/(B32-B30) -> 0.036134899 | F31: =(D31/D32-1)/0.25 -> 0.036321296
B32: 3.5 | C32: =INDEX($F$5:$F$16,MIN(MATCH(B32,$B$5:$B$16,1),11))+(INDEX($F$5:$F$16,MIN(MATCH(B32,$B$5:$B$16,1),11)+1)-INDEX($F$5:$F$16,MIN(MATCH(B32,$B$5:$B$16,1),11)))/(INDEX($B$5:$B$16,MIN(MATCH(B32,$B$5:$B$16,1),11)+1)-INDEX($B$5:$B$16,MIN(MATCH(B32,$B$5:$B$16,1),11)))*(B32-INDEX($B$5:$B$16,MIN(MATCH(B32,$B$5:$B$16,1),11))) -> 0.035865101 | D32: =EXP(-C32*B32) -> 0.8820312 | E32: =(LN(D31)-LN(D33))/(B33-B31) -> 0.036179866 | F32: =(D32/D33-1)/0.25 -> 0.036366671
B33: 3.75 | C33: =INDEX($F$5:$F$16,MIN(MATCH(B33,$B$5:$B$16,1),11))+(INDEX($F$5:$F$16,MIN(MATCH(B33,$B$5:$B$16,1),11)+1)-INDEX($F$5:$F$16,MIN(MATCH(B33,$B$5:$B$16,1),11)))/(INDEX($B$5:$B$16,MIN(MATCH(B33,$B$5:$B$16,1),11)+1)-INDEX($B$5:$B$16,MIN(MATCH(B33,$B$5:$B$16,1),11)))*(B33-INDEX($B$5:$B$16,MIN(MATCH(B33,$B$5:$B$16,1),11))) -> 0.035887584 | D33: =EXP(-C33*B33) -> 0.87408431 | E33: =(LN(D32)-LN(D34))/(B34-B32) -> 0.036224832 | F33: =(D33/D34-1)/0.25 -> 0.036412046
... B57: 9.75 | C57: =INDEX($F$5:$F$16,MIN(MATCH(B57,$B$5:$B$16,1),11))+(INDEX($F$5:$F$16,MIN(MATCH(B57,$B$5:$B$16,1),11)+1)-INDEX($F$5:$F$16,MIN(MATCH(B57,$B$5:$B$16,1),11)))/(INDEX($B$5:$B$16,MIN(MATCH(B57,$B$5:$B$16,1),11)+1)-INDEX($B$5:$B$16,MIN(MATCH(B57,$B$5:$B$16,1),11)))*(B57-INDEX($B$5:$B$16,MIN(MATCH(B57,$B$5:$B$16,1),11))) -> 0.034922935 | D57: =EXP(-C57*B57) -> 0.71141551 | E57: =(LN(D56)-LN(D58))/(B58-B56) -> 0.029131483 | F57: =(D57/D58-1)/0.25 -> 0.02908824
B58: 10 | C58: =INDEX($F$5:$F$16,MIN(MATCH(B58,$B$5:$B$16,1),11))+(INDEX($F$5:$F$16,MIN(MATCH(B58,$B$5:$B$16,1),11)+1)-INDEX($F$5:$F$16,MIN(MATCH(B58,$B$5:$B$16,1),11)))/(INDEX($B$5:$B$16,MIN(MATCH(B58,$B$5:$B$16,1),11)+1)-INDEX($B$5:$B$16,MIN(MATCH(B58,$B$5:$B$16,1),11)))*(B58-INDEX($B$5:$B$16,MIN(MATCH(B58,$B$5:$B$16,1),11))) -> 0.034774436 | D58: =EXP(-C58*B58) -> 0.7062794 | E58: =(LN(D57)-LN(D58))/(B58-B57) -> 0.028982984 | F58: —

Sheet Proj_Curve
B1: Projection Curve · SOFR Futures (0-2Y) + IRS Bootstrap (2-10Y)
B3: SECTION 1 — SOFR FUTURES (Implied 3M Forward Rate per Quarterly Period)
B4: Contract | C4: T_start | D4: T_end | E4: Implied 3M Fwd | F4: Note
B5: Sep25 | C5: 0 | D5: 0.25 | E5: =Instruments!$E$19 -> 0.044 | F5: 3M SOFR forward for Sep25 — directly observed from futures market | H5: =1/(1+E5*0.25) -> 0.98911968
B6: Dec25 | C6: 0.25 | D6: 0.5 | E6: =Instruments!$E$20 -> 0.0425 | F6: 3M SOFR forward for Dec25 — directly observed from futures market
B7: Mar26 | C7: 0.5 | D7: 0.75 | E7: =Instruments!$E$21 -> 0.0408 | F7: 3M SOFR forward for Mar26 — directly observed from futures market
B8: Jun26 | C8: 0.75 | D8: 1 | E8: =Instruments!$E$22 -> 0.0392 | F8: 3M SOFR forward for Jun26 — directly observed from futures market
B9: Sep26 | C9: 1 | D9: 1.25 | E9: =Instruments!$E$23 -> 0.0382 | F9: 3M SOFR forward for Sep26 — directly observed from futures market
B10: Dec26 | C10: 1.25 | D10: 1.5 | E10: =Instruments!$E$24 -> 0.0376 | F10: 3M SOFR forward for Dec26 — directly observed from futures market
B11: Mar27 | C11: 1.5 | D11: 1.75 | E11: =Instruments!$E$25 -> 0.0372 | F11: 3M SOFR forward for Mar27 — directly observed from futures market
B12: Jun27 | C12: 1.75 | D12: 2 | E12: =Instruments!$E$26 -> 0.037 | F12: 3M SOFR forward for Jun27 — directly observed from futures market
B14: SECTION 2 — IRS BOOTSTRAP (Flat Forward per Band, bootstrapped from 3M SOFR IRS)
B15: IRS Mat | C15: Par Rate | D15: Band | E15: Flat Fwd (bootstrapped) | F15: Bootstrap Formula
B16: 3 | C16: =Instruments!$D$30 -> 0.0367 | D16: 2Y-3Y | E16: 0.030563284 | F16: Flat Fwd = (K·Ann(3Y) - PV_Float(0-2Y)) / Ann(2Y-3Y) where Ann=δ·ΣP_OIS(Ti), PV_Float=δ·ΣF_i·P_OIS(Ti)
B17: 5 | C17: =Instruments!$D$31 -> 0.0364 | D17: 3Y-5Y | E17: 0.035908895 | F17: Flat Fwd = (K·Ann(5Y) - PV_Float(0-3Y)) / Ann(3Y-5Y) where Ann=δ·ΣP_OIS(Ti), PV_Float=δ·ΣF_i·P_OIS(Ti)
B18: 7 | C18: =Instruments!$D$32 -> 0.0362 | D18: 5Y-7Y | E18: 0.035634867 | F18: Flat Fwd = (K·Ann(7Y) - PV_Float(0-5Y)) / Ann(5Y-7Y) where Ann=δ·ΣP_OIS(Ti), PV_Float=δ·ΣF_i·P_OIS(Ti)
B19: 10 | C19: =Instruments!$D$33 -> 0.0359 | D19: 7Y-10Y | E19: 0.035066571 | F19: Flat Fwd = (K·Ann(10Y) - PV_Float(0-7Y)) / Ann(7Y-10Y) where Ann=δ·ΣP_OIS(Ti), PV_Float=δ·ΣF_i·P_OIS(Ti)
B21: SECTION 3 — QUARTERLY PROJECTION GRID (40 periods: T_start 0 to 9.75)
B22: T_start | C22: T_end | D22: 3M Forward Rate | E22: Proj DF at T_end | F22: Note
B23: 0 | C23: 0.25 | D23: =E5 -> 0.044 | E23: =1/(1+D23*0.25) -> 0.98911968 | F23: Proj DF(T_end)=Proj DF(T_start)/(1+Fwd·δ) where Proj DF(0)=1
B24: 0.25 | C24: 0.5 | D24: =E6 -> 0.0425 | E24: =E23/(1+D24*0.25) -> 0.97872078 | F24: Proj DF(T_end)=Proj DF(T_start)/(1+Fwd·δ) where Proj DF(0)=1
B25: 0.5 | C25: 0.75 | D25: =E7 -> 0.0408 | E25: =E24/(1+D25*0.25) -> 0.96883862
B26: 0.75 | C26: 1 | D26: =E8 -> 0.0392 | E26: =E25/(1+D26*0.25) -> 0.95943615
B27: 1 | C27: 1.25 | D27: =E9 -> 0.0382 | E27: =E26/(1+D27*0.25) -> 0.95036021
B28: 1.25 | C28: 1.5 | D28: =E10 -> 0.0376 | E28: =E27/(1+D28*0.25) -> 0.94151001
B29: 1.5 | C29: 1.75 | D29: =E11 -> 0.0372 | E29: =E28/(1+D29*0.25) -> 0.93283465
B30: 1.75 | C30: 2 | D30: =E12 -> 0.037 | E30: =E29/(1+D30*0.25) -> 0.92428501
B31: 2 | C31: 2.25 | D31: =E16 -> 0.030563284 | E31: =E30/(1+D31*0.25) -> 0.91727627
B32: 2.25 | C32: 2.5 | D32: =E16 -> 0.030563284 | E32: =E31/(1+D32*0.25) -> 0.91032067
B33: 2.5 | C33: 2.75 | D33: =E16 -> 0.030563284 | E33: =E32/(1+D33*0.25) -> 0.90341782
B34: 2.75 | C34: 3 | D34: =E16 -> 0.030563284 | E34: =E33/(1+D34*0.25) -> 0.89656731
B35: 3 | C35: 3.25 | D35: =E17 -> 0.035908895 | E35: =E34/(1+D35*0.25) -> 0.88859024
B36: 3.25 | C36: 3.5 | D36: =E17 -> 0.035908895 | E36: =E35/(1+D36*0.25) -> 0.88068414
B37: 3.5 | C37: 3.75 | D37: =E17 -> 0.035908895 | E37: =E36/(1+D37*0.25) -> 0.87284838
B38: 3.75 | C38: 4 | D38: =E17 -> 0.035908895 | E38: =E37/(1+D38*0.25) -> 0.86508234
B39: 4 | C39: 4.25 | D39: =E17 -> 0.035908895 | E39: =E38/(1+D39*0.25) -> 0.8573854
B40: 4.25 | C40: 4.5 | D40: =E17 -> 0.035908895 | E40: =E39/(1+D40*0.25) -> 0.84975695
B41: 4.5 | C41: 4.75 | D41: =E17 -> 0.035908895 | E41: =E40/(1+D41*0.25) -> 0.84219636
B42: 4.75 | C42: 5 | D42: =E17 -> 0.035908895 | E42: =E41/(1+D42*0.25) -> 0.83470304
B43: 5 | C43: 5.25 | D43: =E18 -> 0.035634867 | E43: =E42/(1+D43*0.25) -> 0.82733257
...

Sheet Par_Rates
B1: ATM Par Swap Rates · Cap Strike K per Maturity (Dual-Curve Formula)
B2: Par Rate = PV(Float) / Annuity | PV(Float) = δ·Σ F_i·P_OIS(T_i) | Annuity = δ·Σ P_OIS(T_i)
B4: Cap Maturity | C4: Annuity | D4: PV(Floating) | E4: Par Rate K | F4: Market Cap (bps)
B5: 2Y | C5: =0.25*SUM(OIS_Curve!$D$19:$D$26) -> 1.9185229 | D5: =0.25*SUMPRODUCT(Proj_Curve!$D$23:$D$30,OIS_Curve!$D$19:$D$26) -> 0.075993546 | E5: =D5/C5 -> 0.039610444 | F5: 21.897316
B6: 3Y | C6: =0.25*SUM(OIS_Curve!$D$19:$D$30) -> 2.8284158 | D6: =0.25*SUMPRODUCT(Proj_Curve!$D$23:$D$34,OIS_Curve!$D$19:$D$30) -> 0.10380286 | E6: =D6/C6 -> 0.0367 | F6: 69.912719
B7: 5Y | C7: =0.25*SUM(OIS_Curve!$D$19:$D$38) -> 4.555022 | D7: =0.25*SUMPRODUCT(Proj_Curve!$D$23:$D$42,OIS_Curve!$D$19:$D$38) -> 0.16580338 | E7: =D7/C7 -> 0.036400127 | F7: 143.36482
B8: 7Y | C8: =0.25*SUM(OIS_Curve!$D$19:$D$46) -> 6.1658681 | D8: =0.25*SUMPRODUCT(Proj_Curve!$D$23:$D$50,OIS_Curve!$D$19:$D$46) -> 0.22320567 | E8: =D8/C8 -> 0.036200201 | F8: 219.15872
B9: 10Y | C9: =0.25*SUM(OIS_Curve!$D$19:$D$58) -> 8.3820774 | D9: =0.25*SUMPRODUCT(Proj_Curve!$D$23:$D$62,OIS_Curve!$D$19:$D$58) -> 0.30092053 | E9: =D9/C9 -> 0.035900471 | F9: 333.79573

Sheet HW_Caplets
B1: HW Caplet Pricing · Organised by Cap Maturity · Formula-driven
B2: Caplet = (1+Kδ)·[K̃·P(0,S)·Φ(-h+σ_p) - P(0,S+δ)·Φ(-h)] | σ_p=(σ/a)·(1-e^{-aδ})·√[(1-e^{-2aS})/(2a)] | h=(1/σ_p)·ln[P(0,S+δ)/(P(0,S)·K̃)]+σ_p/2 | K̃=1/(1+Kδ)
B3: 2Y Cap · K = 3.961% · 7 caplets (T_start = 0.25 to 1.75)
B4: T_start | C4: T_end | D4: P(0,S) | E4: P(0,S+δ) | F4: K | G4: K̃ | H4: σ_p | I4: h | J4: Φ(-h+σ_p) | K4: Φ(-h) | L4: Caplet (dec) | M4: Caplet (bps)
B5: 0.25 | C5: 0.5 | D5: =VLOOKUP(B5,OIS_Curve!$B$19:$D$58,3,FALSE()) -> 0.98973154 | E5: =VLOOKUP(C5,OIS_Curve!$B$19:$D$58,3,FALSE()) -> 0.98039216 | F5: =Par_Rates!$E$5 -> 0.039610444 | G5: =1/(1+F5*0.25) -> 0.99019449 | H5: =IF(B5=0,0,(Parameters!$C$5/Parameters!$C$4)*(1-EXP(-Parameters!$C$4*0.25))*SQRT((1-EXP(-2*Parameters!$C$4*B5))/(2*Parameters!$C$4))) -> 0.00097241305 | I5: =IF(H5=0,0,(1/H5)*LN(E5/(D5*G5))+H5/2) -> 0.38388635 | J5: =NORMSDIST(-I5+H5) -> 0.35089179 | K5: =NORMSDIST(-I5) -> 0.35053134 | L5: =IF(H5=0,0,(1+F5*0.25)*(G5*D5*J5-E5*K5)) -> 0.00022737711 | M5: =L5*10000 -> 2.2737711
B6: 0.5 | C6: 0.75 | D6: =VLOOKUP(B6,OIS_Curve!$B$19:$D$58,3,FALSE()) -> 0.98039216 | E6: =VLOOKUP(C6,OIS_Curve!$B$19:$D$58,3,FALSE()) -> 0.97157395 | F6: =Par_Rates!$E$5 -> 0.039610444 | G6: =1/(1+F6*0.25) -> 0.99019449 | H6: =IF(B6=0,0,(Parameters!$C$5/Parameters!$C$4)*(1-EXP(-Parameters!$C$4*0.25))*SQRT((1-EXP(-2*Parameters!$C$4*B6))/(2*Parameters!$C$4))) -> 0.0013481001 | I6: =IF(H6=0,0,(1/H6)*LN(E6/(D6*G6))+H6/2) -> 0.60792795 | J6: =NORMSDIST(-I6+H6) -> 0.27206489 | K6: =NORMSDIST(-I6) -> 0.27161763 | L6: =IF(H6=0,0,(1+F6*0.25)*(G6*D6*J6-E6*K6)) -> 0.00022040156 | M6: =L6*10000 -> 2.2040156
B7: 0.75 | C7: 1 | D7: =VLOOKUP(B7,OIS_Curve!$B$19:$D$58,3,FALSE()) -> 0.97157395 | E7: =VLOOKUP(C7,OIS_Curve!$B$19:$D$58,3,FALSE()) -> 0.96339114 | F7: =Par_Rates!$E$5 -> 0.039610444 | G7: =1/(1+F7*0.25) -> 0.99019449 | H7: =IF(B7=0,0,(Parameters!$C$5/Parameters!$C$4)*(1-EXP(-Parameters!$C$4*0.25))*SQRT((1-EXP(-2*Parameters!$C$4*B7))/(2*Parameters!$C$4))) -> 0.0016189875 | I7: =IF(H7=0,0,(1/H7)*LN(E7/(D7*G7))+H7/2) -> 0.86308085 | J7: =NORMSDIST(-I7+H7) -> 0.19449186 | K7: =NORMSDIST(-I7) -> 0.19404651 | L7: =IF(H7=0,0,(1+F7*0.25)*(G7*D7*J7-E7*K7)) -> 0.00016931734 | M7: =L7*10000 -> 1.6931734
B8: 1 | C8: 1.25 | D8: =VLOOKUP(B8,OIS_Curve!$B$19:$D$58,3,FALSE()) -> 0.96339114 | E8: =VLOOKUP(C8,OIS_Curve!$B$19:$D$58,3,FALSE()) -> 0.95474312 | F8: =Par_Rates!$E$5 -> 0.039610444 | G8: =1/(1+F8*0.25) -> 0.99019449 | H8: =IF(B8=0,0,(Parameters!$C$5/Parameters!$C$4)*(1-EXP(-Parameters!$C$4*0.25))*SQRT((1-EXP(-2*Parameters!$C$4*B8))/(2*Parameters!$C$4))) -> 0.0018336131 | I8: =IF(H8=0,0,(1/H8)*LN(E8/(D8*G8))+H8/2) -> 0.45724519 | J8: =NORMSDIST(-I8+H8) -> 0.32440658 | K8: =NORMSDIST(-I8) -> 0.32374741 | L8: =IF(H8=0,0,(1+F8*0.25)*(G8*D8*J8-E8*K8)) -> 0.00037396084 | M8: =L8*10000 -> 3.7396084
B9: 1.25 | C9: 1.5 | D9: =VLOOKUP(B9,OIS_Curve!$B$19:$D$58,3,FALSE()) -> 0.95474312 | E9: =VLOOKUP(C9,OIS_Curve!$B$19:$D$58,3,FALSE()) -> 0.94628885 | F9: =Par_Rates!$E$5 -> 0.039610444 | G9: =1/(1+F9*0.25) -> 0.99019449 | H9: =IF(B9=0,0,(Parameters!$C$5/Parameters!$C$4)*(1-EXP(-Parameters!$C$4*0.25))*SQRT((1-EXP(-2*Parameters!$C$4*B9))/(2*Parameters!$C$4))) -> 0.0020112979 | I9: =IF(H9=0,0,(1/H9)*LN(E9/(D9*G9))+H9/2) -> 0.47803068 | J9: =NORMSDIST(-I9+H9) -> 0.31703029 | K9: =NORMSDIST(-I9) -> 0.31631418 | L9: =IF(H9=0,0,(1+F9*0.25)*(G9*D9*J9-E9*K9)) -> 0.00039380335 | M9: =L9*10000 -> 3.9380335
B10: 1.5 | C10: 1.75 | D10: =VLOOKUP(B10,OIS_Curve!$B$19:$D$58,3,FALSE()) -> 0.94628885 | E10: =VLOOKUP(C10,OIS_Curve!$B$19:$D$58,3,FALSE()) -> 0.93802454 | F10: =Par_Rates!$E$5 -> 0.039610444 | G10: =1/(1+F10*0.25) -> 0.99019449 | H10: =IF(B10=0,0,(Parameters!$C$5/Parameters!$C$4)*(1-EXP(-Parameters!$C$4*0.25))*SQRT((1-EXP(-2*Parameters!$C$4*B10))/(2*Parameters!$C$4))) -> 0.0021622167 | I10: =IF(H10=0,0,(1/H10)*LN(E10/(D10*G10))+H10/2) -> 0.50156248 | J10: =NORMSDIST(-I10+H10) -> 0.30874872 | K10: =NORMSDIST(-I10) -> 0.30798766 | L10: =IF(H10=0,0,(1+F10*0.25)*(G10*D10*J10-E10*K10)) -> 0.00040462284 | M10: =L10*10000 -> 4.0462284
B11: 1.75 | C11: 2 | D11: =VLOOKUP(B11,OIS_Curve!$B$19:$D$58,3,FALSE()) -> 0.93802454 | E11: =VLOOKUP(C11,OIS_Curve!$B$19:$D$58,3,FALSE()) -> 0.92994651 | F11: =Par_Rates!$E$5 -> 0.039610444 | G11: =1/(1+F11*0.25) -> 0.99019449 | H11: =IF(B11=0,0,(Parameters!$C$5/Parameters!$C$4)*(1-EXP(-Parameters!$C$4*0.25))*SQRT((1-EXP(-2*Parameters!$C$4*B11))/(2*Parameters!$C$4))) -> 0.0022925715 | I11: =IF(H11=0,0,(1/H11)*LN(E11/(D11*G11))+H11/2) -> 0.52669539 | J11: =NORMSDIST(-I11+H11) -> 0.2999992 | K11: =NORMSDIST(-I11) -> 0.29920257 | L11: =IF(H11=0,0,(1+F11*0.25)*(G11*D11*J11-E11*K11)) -> 0.00040889935 | M11: =L11*10000 -> 4.0889935
B12: Cap 2Y Total (Model) | L12: =SUM(L5:L11) -> 0.0021983824 | M12: =SUM(M5:M11) -> 21.983824
B14: 3Y Cap · K = 3.670% · 11 caplets (T_start = 0.25 to 2.75)
B15: T_start | C15: T_end | D15: P(0,S) | E15: P(0,S+δ) | F15: K | G15: K̃ | H15: σ_p | I15: h | J15: Φ(-h+σ_p) | K15: Φ(-h) | L15: Caplet (dec) | M15: Caplet (bps)
B16: 0.25 | C16: 0.5 | D16: =VLOOKUP(B16,OIS_Curve!$B$19:$D$58,3,FALSE()) -> 0.98973154 | E16: =VLOOKUP(C16,OIS_Curve!$B$19:$D$58,3,FALSE()) -> 0.98039216 | F16: =Par_Rates!$E$6 -> 0.0367 | G16: =1/(1+F16*0.25) -> 0.99090842 | H16: =IF(B16=0,0,(Parameters!$C$5/Parameters!$C$4)*(1-EXP(-Parameters!$C$4*0.25))*SQRT((1-EXP(-2*Parameters!$C$4*B16))/(2*Parameters!$C$4))) -> 0.00097241305 | I16: =IF(H16=0,0,(1/H16)*LN(E16/(D16*G16))+H16/2) -> -0.35729678 | J16: =NORMSDIST(-I16+H16) -> 0.63992906 | K16: =NORMSDIST(-I16) -> 0.63956518 | L16: =IF(H16=0,0,(1+F16*0.25)*(G16*D16*J16-E16*K16)) -> 0.00058033818 | M16: =L16*10000 -> 5.8033818
B17: 0.5 | C17: 0.75 | D17: =VLOOKUP(B17,OIS_Curve!$B$19:$D$58,3,FALSE()) -> 0.98039216 | E17: =VLOOKUP(C17,OIS_Curve!$B$19:$D$58,3,FALSE()) -> 0.97157395 | F17: =Par_Rates!$E$6 -> 0.0367 | G17: =1/(1+F17*0.25) -> 0.99090842 | H17: =IF(B17=0,0,(Parameters!$C$5/Parameters!$C$4)*(1-EXP(-Parameters!$C$4*0.25))*SQRT((1-EXP(-2*Parameters!$C$4*B17))/(2*Parameters!$C$4))) -> 0.0013481001 | I17: =IF(H17=0,0,(1/H17)*LN(E17/(D17*G17))+H17/2) -> 0.073296939 | J17: =NORMSDIST(-I17+H17) -> 0.47132131 | K17: =NORMSDIST(-I17) -> 0.47078491 | L17: =IF(H17=0,0,(1+F17*0.25)*(G17*D17*J17-E17*K17)) -> 0.00048069045 | M17: =L17*10000 -> 4.8069045
B18: 0.75 | C18: 1 | D18: =VLOOKUP(B18,OIS_Curve!$B$19:$D$58,3,FALSE()) -> 0.97157395 | E18: =VLOOKUP(C18,OIS_Curve!$B$19:$D$58,3,FALSE()) -> 0.96339114 | F18: =Par_Rates!$E$6 -> 0.0367 | G18: =1/(1+F18*0.25) -> 0.99090842 | H18: =IF(B18=0,0,(Parameters!$C$5/Parameters!$C$4)*(1-EXP(-Parameters!$C$4*0.25))*SQRT((1-EXP(-2*Parameters!$C$4*B18))/(2*Parameters!$C$4))) -> 0.0016189875 | I18: =IF(H18=0,0,(1/H18)*LN(E18/(D18*G18))+H18/2) -> 0.41790376 | J18: =NORMSDIST(-I18+H18) -> 0.33860082 | K18: =NORMSDIST(-I18) -> 0.33800874 | L18: =IF(H18=0,0,(1+F18*0.25)*(G18*D18*J18-E18*K18)) -> 0.0003534109 | M18: =L18*10000 -> 3.534109
B19: 1 | C19: 1.25 | D19: =VLOOKUP(B19,OIS_Curve!$B$19:$D$58,3,FALSE()) -> 0.96339114 | E19: =VLOOKUP(C19,OIS_Curve!$B$19:$D$58,3,FALSE()) -> 0.95474312 | F19: =Par_Rates!$E$6 -> 0.0367 | G19: =1/(1+F19*0.25) -> 0.99090842 | H19: =IF(B19=0,0,(Parameters!$C$5/Parameters!$C$4)*(1-EXP(-Parameters!$C$4*0.25))*SQRT((1-EXP(-2*Parameters!$C$4*B19))/(2*Parameters!$C$4))) -> 0.0018336131 | I19: =IF(H19=0,0,(1/H19)*LN(E19/(D19*G19))+H19/2) -> 0.06417636 | J19: =NORMSDIST(-I19+H19) -> 0.47514494 | K19: =NORMSDIST(-I19) -> 0.4744149 | L19: =IF(H19=0,0,(1+F19*0.25)*(G19*D19*J19-E19*K19)) -> 0.00065029983 | M19: =L19*10000 -> 6.5029983
B20: 1.25 | C20: 1.5 | D20: =VLOOKUP(B20,OIS_Curve!$B$19:$D$58,3,FALSE()) -> 0.95474312 | E20: =VLOOKUP(C20,OIS_Curve!$B$19:$D$58,3,FALSE()) -> 0.94628885 | F20: =Par_Rates!$E$6 -> 0.0367 | G20: =1/(1+F20*0.25) -> 0.99090842 | H20: =IF(B20=0,0,(Parameters!$C$5/Parameters!$C$4)*(1-EXP(-Parameters!$C$4*0.25))*SQRT((1-EXP(-2*Parameters!$C$4*B20))/(2*Parameters!$C$4))) -> 0.0020112979 | I20: =IF(H20=0,0,(1/H20)*LN(E20/(D20*G20))+H20/2) -> 0.11968687 | J20: =NORMSDIST(-I20+H20) -> 0.45316236 | K20: =NORMSDIST(-I20) -> 0.4523656 | L20: =IF(H20=0,0,(1+F20*0.25)*(G20*D20*J20-E20*K20)) -> 0.00065759508 | M20: =L20*10000 -> 6.5759508
B21: 1.5 | C21: 1.75 | D21: =VLOOKUP(B21,OIS_Curve!$B$19:$D$58,3,FALSE()) -> 0.94628885 | E21: =VLOOKUP(C21,OIS_Curve!$B$19:$D$58,3,FALSE()) -> 0.93802454 | F21: =Par_Rates!$E$6 -> 0.0367 | G21: =1/(1+F21*0.25) -> 0.99090842 | H21: =IF(B21=0,0,(Parameters!$C$5/Parameters!$C$4)*(1-EXP(-Parameters!$C$4*0.25))*SQRT((1-EXP(-2*Parameters!$C$4*B21))/(2*Parameters!$C$4))) -> 0.0021622167 | I21: =IF(H21=0,0,(1/H21)*LN(E21/(D21*G21))+H21/2) -> 0.16823042 | J21: =NORMSDIST(-I21+H21) -> 0.43405164 | K21: =NORMSDIST(-I21) -> 0.43320101 | L21: =IF(H21=0,0,(1+F21*0.25)*(G21*D21*J21-E21*K21)) -> 0.00065676274 | M21: =L21*10000 -> 6.5676274
B22: 1.75 | C22: 2 | D22: =VLOOKUP(B22,OIS_Curve!$B$19:$D$58,3,FALSE()) -> 0.93802454 | E22: =VLOOKUP(C22,OIS_Curve!$B$19:$D$58,3,FALSE()) -> 0.92994651 | F22: =Par_Rates!$E$6 -> 0.0367 | G22: =1/(1+F22*0.25) -> 0.99090842 | H22: =IF(B22=0,0,(Parameters!$C$5/Parameters!$C$4)*(1-EXP(-Parameters!$C$4*0.25))*SQRT((1-EXP(-2*Parameters!$C$4*B22))/(2*Parameters!$C$4))) -> 0.0022925715 | I22: =IF(H22=0,0,(1/H22)*LN(E22/(D22*G22))+H22/2) -> 0.21231648 | J22: =NORMSDIST(-I22+H22) -> 0.41682451 | K22: =NORMSDIST(-I22) -> 0.41593007 | L22: =IF(H22=0,0,(1+F22*0.25)*(G22*D22*J22-E22*K22)) -> 0.00065007615 | M22: =L22*10000 -> 6.5007615
B23: 2 | C23: 2.25 | D23: =VLOOKUP(B23,OIS_Curve!$B$19:$D$58,3,FALSE()) -> 0.92994651 | E23: =VLOOKUP(C23,OIS_Curve!$B$19:$D$58,3,FALSE()) -> 0.92179827 | F23: =Par_Rates!$E$6 -> 0.0367 | G23: =1/(1+F23*0.25) -> 0.99090842 | H23: =IF(B23=0,0,(Parameters!$C$5/Parameters!$C$4)*(1-EXP(-Parameters!$C$4*0.25))*SQRT((1-EXP(-2*Parameters!$C$4*B23))/(2*Parameters!$C$4))) -> 0.0024065047 | I23: =IF(H23=0,0,(1/H23)*LN(E23/(D23*G23))+H23/2) -> 0.13936975 | J23: =NORMSDIST(-I23+H23) -> 0.44552992 | K23: =NORMSDIST(-I23) -> 0.44457899 | L23: =IF(H23=0,0,(1+F23*0.25)*(G23*D23*J23-E23*K23)) -> 0.00074683052 | M23: =L23*10000 -> 7.4683052
B24: 2.25 | C24: 2.5 | D24: =VLOOKUP(B24,OIS_Curve!$B$19:$D$58,3,FALSE()) -> 0.92179827 | E24: =VLOOKUP(C24,OIS_Curve!$B$19:$D$58,3,FALSE()) -> 0.91377784 | F24: =Par_Rates!$E$6 -> 0.0367 | G24: =1/(1+F24*0.25) -> 0.99090842 | H24: =IF(B24=0,0,(Parameters!$C$5/Parameters!$C$4)*(1-EXP(-Parameters!$C$4*0.25))*SQRT((1-EXP(-2*Parameters!$C$4*B24))/(2*Parameters!$C$4))) -> 0.0025069625 | I24: =IF(H24=0,0,(1/H24)*LN(E24/(D24*G24))+H24/2) -> 0.15851348 | J24: =NORMSDIST(-I24+H24) -> 0.43801394 | K24: =NORMSDIST(-I24) -> 0.4370261 | L24: =IF(H24=0,0,(1+F24*0.25)*(G24*D24*J24-E24*K24)) -> 0.00075173841 | M24: =L24*10000 -> 7.5173841
B25: 2.5 | C25: 2.75 | D25: =VLOOKUP(B25,OIS_Curve!$B$19:$D$58,3,FALSE()) -> 0.91377784 | E25: =VLOOKUP(C25,OIS_Curve!$B$19:$D$58,3,FALSE()) -> 0.90588313 | F25: =Par_Rates!$E$6 -> 0.0367 | G25: =1/(1+F25*0.25) -> 0.99090842 | H25: =IF(B25=0,0,(Parameters!$C$5/Parameters!$C$4)*(1-EXP(-Parameters!$C$4*0.25))*SQRT((1-EXP(-2*Parameters!$C$4*B25))/(2*Parameters!$C$4))) -> 0.0025961381 | I25: =IF(H25=0,0,(1/H25)*LN(E25/(D25*G25))+H25/2) -> 0.17694031 | J25: =NORMSDIST(-I25+H25) -> 0.43079749 | K25: =NORMSDIST(-I25) -> 0.42977764 | L25: =IF(H25=0,0,(1+F25*0.25)*(G25*D25*J25-E25*K25)) -> 0.00075280309 | M25: =L25*10000 -> 7.5280309
B26: 2.75 | C26: 3 | D26: =VLOOKUP(B26,OIS_Curve!$B$19:$D$58,3,FALSE()) -> 0.90588313 | E26: =VLOOKUP(C26,OIS_Curve!$B$19:$D$58,3,FALSE()) -> 0.89811208 | F26: =Par_Rates!$E$6 -> 0.0367 | G26: =1/(1+F26*0.25) -> 0.99090842 | H26: =IF(B26=0,0,(Parameters!$C$5/Parameters!$C$4)*(1-EXP(-Parameters!$C$4*0.25))*SQRT((1-EXP(-2*Parameters!$C$4*B26))/(2*Parameters!$C$4))) -> 0.002675722 | I26: =IF(H26=0,0,(1/H26)*LN(E26/(D26*G26))+H26/2) -> 0.19483259 | J26: =NORMSDIST(-I26+H26) -> 0.42380967 | K26: =NORMSDIST(-I26) -> 0.42276201 | L26: =IF(H26=0,0,(1+F26*0.25)*(G26*D26*J26-E26*K26)) -> 0.00075072765 | M26: =L26*10000 -> 7.5072765
B27: Cap 3Y Total (Model) | L27: =SUM(L16:L26) -> 0.007031273 | M27: =SUM(M16:M26) -> 70.31273
B29: 5Y Cap · K = 3.640% · 19 caplets (T_start = 0.25 to 4.75)
B30: T_start | C30: T_end | D30: P(0,S) | E30: P(0,S+δ) | F30: K | G30: K̃ | H30: σ_p | I30: h | J30: Φ(-h+σ_p) | K30: Φ(-h) | L30: Caplet (dec) | M30: Caplet (bps)
B31: 0.25 | C31: 0.5 | D31: =VLOOKUP(B31,OIS_Curve!$B$19:$D$58,3,FALSE()) -> 0.98973154 | E31: =VLOOKUP(C31,OIS_Curve!$B$19:$D$58,3,FALSE()) -> 0.98039216 | F31: =Par_Rates!$E$7 -> 0.036400127 | G31: =1/(1+F31*0.25) -> 0.99098203 | H31: =IF(B31=0,0,(Parameters!$C$5/Parameters!$C$4)*(1-EXP(-Parameters!$C$4*0.25))*SQRT((1-EXP(-2*Parameters!$C$4*B31))/(2*Parameters!$C$4))) -> 0.00097241305 | I31: =IF(H31=0,0,(1/H31)*LN(E31/(D31*G31))+H31/2) -> -0.43369367 | J31: =NORMSDIST(-I31+H31) -> 0.66809759 | K31: =NORMSDIST(-I31) -> 0.66774455 | L31: =IF(H31=0,0,(1+F31*0.25)*(G31*D31*J31-E31*K31)) -> 0.00062838583 | M31: =L31*10000 -> 6.2838583
B32: 0.5 | C32: 0.75 | D32: =VLOOKUP(B32,OIS_Curve!$B$19:$D$58,3,FALSE()) -> 0.98039216 | E32: =VLOOKUP(C32,OIS_Curve!$B$19:$D$58,3,FALSE()) -> 0.97157395 | F32: =Par_Rates!$E$7 -> 0.036400127 | G32: =1/(1+F32*0.25) -> 0.99098203 | H32: =IF(B32=0,0,(Parameters!$C$5/Parameters!$C$4)*(1-EXP(-Parameters!$C$4*0.25))*SQRT((1-EXP(-2*Parameters!$C$4*B32))/(2*Parameters!$C$4))) -> 0.0013481001 | I32: =IF(H32=0,0,(1/H32)*LN(E32/(D32*G32))+H32/2) -> 0.018190254 | J32: =NORMSDIST(-I32+H32) -> 0.49328127 | K32: =NORMSDIST(-I32) -> 0.49274354 | L32: =IF(H32=0,0,(1+F32*0.25)*(G32*D32*J32-E32*K32)) -> 0.00051578041 | M32: =L32*10000 -> 5.1578041
B33: 0.75 | C33: 1 | D33: =VLOOKUP(B33,OIS_Curve!$B$19:$D$58,3,FALSE()) -> 0.97157395 | E33: =VLOOKUP(C33,OIS_Curve!$B$19:$D$58,3,FALSE()) -> 0.96339114 | F33: =Par_Rates!$E$7 -> 0.036400127 | G33: =1/(1+F33*0.25) -> 0.99098203 | H33: =IF(B33=0,0,(Parameters!$C$5/Parameters!$C$4)*(1-EXP(-Parameters!$C$4*0.25))*SQRT((1-EXP(-2*Parameters!$C$4*B33))/(2*Parameters!$C$4))) -> 0.0016189875 | I33: =IF(H33=0,0,(1/H33)*LN(E33/(D33*G33))+H33/2) -> 0.37201747 | J33: =NORMSDIST(-I33+H33) -> 0.3555428 | K33: =NORMSDIST(-I33) -> 0.35493992 | L33: =IF(H33=0,0,(1+F33*0.25)*(G33*D33*J33-E33*K33)) -> 0.00037843268 | M33: =L33*10000 -> 3.7843268
B34: 1 | C34: 1.25 | D34: =VLOOKUP(B34,OIS_Curve!$B$19:$D$58,3,FALSE()) -> 0.96339114 | E34: =VLOOKUP(C34,OIS_Curve!$B$19:$D$58,3,FALSE()) -> 0.95474312 | F34: =Par_Rates!$E$7 -> 0.036400127 | G34: =1/(1+F34*0.25) -> 0.99098203 | H34: =IF(B34=0,0,(Parameters!$C$5/Parameters!$C$4)*(1-EXP(-Parameters!$C$4*0.25))*SQRT((1-EXP(-2*Parameters!$C$4*B34))/(2*Parameters!$C$4))) -> 0.0018336131 | I34: =IF(H34=0,0,(1/H34)*LN(E34/(D34*G34))+H34/2) -> 0.02366109 | J34: =NORMSDIST(-I34+H34) -> 0.49129279 | K34: =NORMSDIST(-I34) -> 0.49056147 | L34: =IF(H34=0,0,(1+F34*0.25)*(G34*D34*J34-E34*K34)) -> 0.0006848339 | M34: =L34*10000 -> 6.848339
B35: 1.25 | C35: 1.5 | D35: =VLOOKUP(B35,OIS_Curve!$B$19:$D$58,3,FALSE()) -> 0.95474312 | E35: =VLOOKUP(C35,OIS_Curve!$B$19:$D$58,3,FALSE()) -> 0.94628885 | F35: =Par_Rates!$E$7 -> 0.036400127 | G35: =1/(1+F35*0.25) -> 0.99098203 | H35: =IF(B35=0,0,(Parameters!$C$5/Parameters!$C$4)*(1-EXP(-Parameters!$C$4*0.25))*SQRT((1-EXP(-2*Parameters!$C$4*B35))/(2*Parameters!$C$4))) -> 0.0020112979 | I35: =IF(H35=0,0,(1/H35)*LN(E35/(D35*G35))+H35/2) -> 0.082750853 | J35: =NORMSDIST(-I35+H35) -> 0.46782454 | K35: =NORMSDIST(-I35) -> 0.46702482 | L35: =IF(H35=0,0,(1+F35*0.25)*(G35*D35*J35-E35*K35)) -> 0.00069020622 | M35: =L35*10000 -> 6.9020622
B36: 1.5 | C36: 1.75 | D36: =VLOOKUP(B36,OIS_Curve!$B$19:$D$58,3,FALSE()) -> 0.94628885 | E36: =VLOOKUP(C36,OIS_Curve!$B$19:$D$58,3,FALSE()) -> 0.93802454 | F36: =Par_Rates!$E$7 -> 0.036400127 | G36: =1/(1+F36*0.25) -> 0.99098203 | H36: =IF(B36=0,0,(Parameters!$C$5/Parameters!$C$4)*(1-EXP(-Parameters!$C$4*0.25))*SQRT((1-EXP(-2*Parameters!$C$4*B36))/(2*Parameters!$C$4))) -> 0.0021622167 | I36: =IF(H36=0,0,(1/H36)*LN(E36/(D36*G36))+H36/2) -> 0.13387247 | J36: =NORMSDIST(-I36+H36) -> 0.44760674 | K36: =NORMSDIST(-I36) -> 0.44675171 | L36: =IF(H36=0,0,(1+F36*0.25)*(G36*D36*J36-E36*K36)) -> 0.00068770232 | M36: =L36*10000 -> 6.8770232
B37: 1.75 | C37: 2 | D37: =VLOOKUP(B37,OIS_Curve!$B$19:$D$58,3,FALSE()) -> 0.93802454 | E37: =VLOOKUP(C37,OIS_Curve!$B$19:$D$58,3,FALSE()) -> 0.92994651 | F37: =Par_Rates!$E$7 -> 0.036400127 | G37: =1/(1+F37*0.25) -> 0.99098203 | H37: =IF(B37=0,0,(Parameters!$C$5/Parameters!$C$4)*(1-EXP(-Parameters!$C$4*0.25))*SQRT((1-EXP(-2*Parameters!$C$4*B37))/(2*Parameters!$C$4))) -> 0.0022925715 | I37: =IF(H37=0,0,(1/H37)*LN(E37/(D37*G37))+H37/2) -> 0.17991211 | J37: =NORMSDIST(-I37+H37) -> 0.42951089 | K37: =NORMSDIST(-I37) -> 0.42861078 | L37: =IF(H37=0,0,(1+F37*0.25)*(G37*D37*J37-E37*K37)) -> 0.00067951484 | M37: =L37*10000 -> 6.7951484
B38: 2 | C38: 2.25 | D38: =VLOOKUP(B38,OIS_Curve!$B$19:$D$58,3,FALSE()) -> 0.92994651 | E38: =VLOOKUP(C38,OIS_Curve!$B$19:$D$58,3,FALSE()) -> 0.92179827 | F38: =Par_Rates!$E$7 -> 0.036400127 | G38: =1/(1+F38*0.25) -> 0.99098203 | H38: =IF(B38=0,0,(Parameters!$C$5/Parameters!$C$4)*(1-EXP(-Parameters!$C$4*0.25))*SQRT((1-EXP(-2*Parameters!$C$4*B38))/(2*Parameters!$C$4))) -> 0.0024065047 | I38: =IF(H38=0,0,(1/H38)*LN(E38/(D38*G38))+H38/2) -> 0.10849953 | J38: =NORMSDIST(-I38+H38) -> 0.45775427 | K38: =NORMSDIST(-I38) -> 0.45679973 | L38: =IF(H38=0,0,(1+F38*0.25)*(G38*D38*J38-E38*K38)) -> 0.00077797537 | M38: =L38*10000 -> 7.7797537
B39: 2.25 | C39: 2.5 | D39: =VLOOKUP(B39,OIS_Curve!$B$19:$D$58,3,FALSE()) -> 0.92179827 | E39: =VLOOKUP(C39,OIS_Curve!$B$19:$D$58,3,FALSE()) -> 0.91377784 | F39: =Par_Rates!$E$7 -> 0.036400127 | G39: =1/(1+F39*0.25) -> 0.99098203 | H39: =IF(B39=0,0,(Parameters!$C$5/Parameters!$C$4)*(1-EXP(-Parameters!$C$4*0.25))*SQRT((1-EXP(-2*Parameters!$C$4*B39))/(2*Parameters!$C$4))) -> 0.0025069625 | I39: =IF(H39=0,0,(1/H39)*LN(E39/(D39*G39))+H39/2) -> 0.12888028 | J39: =NORMSDIST(-I39+H39) -> 0.44971821 | K39: =NORMSDIST(-I39) -> 0.44872619 | L39: =IF(H39=0,0,(1+F39*0.25)*(G39*D39*J39-E39*K39)) -> 0.00078207701 | M39: =L39*10000 -> 7.8207701
B40: 2.5 | C40: 2.75 | D40: =VLOOKUP(B40,OIS_Curve!$B$19:$D$58,3,FALSE()) -> 0.91377784 | E40: =VLOOKUP(C40,OIS_Curve!$B$19:$D$58,3,FALSE()) -> 0.90588313 | F40: =Par_Rates!$E$7 -> 0.036400127 | G40: =1/(1+F40*0.25) -> 0.99098203 | H40: =IF(B40=0,0,(Parameters!$C$5/Parameters!$C$4)*(1-EXP(-Parameters!$C$4*0.25))*SQRT((1-EXP(-2*Parameters!$C$4*B40))/(2*Parameters!$C$4))) -> 0.0025961381 | I40: =IF(H40=0,0,(1/H40)*LN(E40/(D40*G40))+H40/2) -> 0.14832498 | J40: =NORMSDIST(-I40+H40) -> 0.44206772 | K40: =NORMSDIST(-I40) -> 0.44104315 | L40: =IF(H40=0,0,(1+F40*0.25)*(G40*D40*J40-E40*K40)) -> 0.00078237254 | M40: =L40*10000 -> 7.8237254
B41: 2.75 | C41: 3 | D41: =VLOOKUP(B41,OIS_Curve!$B$19:$D$58,3,FALSE()) -> 0.90588313 | E41: =VLOOKUP(C41,OIS_Curve!$B$19:$D$58,3,FALSE()) -> 0.89811208 | F41: =Par_Rates!$E$7 -> 0.036400127 | G41: =1/(1+F41*0.25) -> 0.99098203 | H41: =IF(B41=0,0,(Parameters!$C$5/Parameters!$C$4)*(1-EXP(-Parameters!$C$4*0.25))*SQRT((1-EXP(-2*Parameters!$C$4*B41))/(2*Parameters!$C$4))) -> 0.002675722 | I41: =IF(H41=0,0,(1/H41)*LN(E41/(D41*G41))+H41/2) -> 0.16706837 | J41: =NORMSDIST(-I41+H41) -> 0.43471103 | K41: =NORMSDIST(-I41) -> 0.43365813 | L41: =IF(H41=0,0,(1+F41*0.25)*(G41*D41*J41-E41*K41)) -> 0.00077955864 | M41: =L41*10000 -> 7.7955864
B42: 3 | C42: 3.25 | D42: =VLOOKUP(B42,OIS_Curve!$B$19:$D$58,3,FALSE()) -> 0.89811208 | E42: =VLOOKUP(C42,OIS_Curve!$B$19:$D$58,3,FALSE()) -> 0.89004033 | F42: =Par_Rates!$E$7 -> 0.036400127 | G42: =1/(1+F42*0.25) -> 0.99098203 | H42: =IF(B42=0,0,(Parameters!$C$5/Parameters!$C$4)*(1-EXP(-Parameters!$C$4*0.25))*SQRT((1-EXP(-2*Parameters!$C$4*B42))/(2*Parameters!$C$4))) -> 0.0027470527 | I42: =IF(H42=0,0,(1/H42)*LN(E42/(D42*G42))+H42/2) -> 0.012575352 | J42: =NORMSDIST(-I42+H42) -> 0.49607914 | K42: =NORMSDIST(-I42) -> 0.49498329 | L42: =IF(H42=0,0,(1+F42*0.25)*(G42*D42*J42-E42*K42)) -> 0.00097051294 | M42: =L42*10000 -> 9.7051294
...

Sheet TRY_Caplets
B1: PRACTICE: HW Caplet Pricing · Yellow cells = YOUR TURN · Check col shows OK/CHECK
B2: Caplet = (1+Kδ)·[K̃·P(0,S)·Φ(-h+σ_p) - P(0,S+δ)·Φ(-h)] | σ_p=(σ/a)·(1-e^{-aδ})·√[(1-e^{-2aS})/(2a)] | h=(1/σ_p)·ln[P(0,S+δ)/(P(0,S)·K̃)]+σ_p/2 | K̃=1/(1+Kδ)
B3: 2Y Cap · K = 3.961% · 7 caplets (T_start = 0.25 to 1.75) | O3: Check vs Solution
B4: T_start | C4: T_end | D4: P(0,S) | E4: P(0,S+δ) | F4: K | G4: K̃ | H4: σ_p | I4: h | J4: Φ(-h+σ_p) | K4: Φ(-h) | L4: Caplet (dec) | M4: Caplet (bps)
B5: 0.25 | C5: 0.5 | D5: =VLOOKUP(B5,OIS_Curve!$B$19:$D$58,3,FALSE()) -> 0.98973154 | E5: =VLOOKUP(C5,OIS_Curve!$B$19:$D$58,3,FALSE()) -> 0.98039216 | F5: =Par_Rates!$E$5 -> 0.039610444 | G5: =1/(1+F5*0.25) -> 0.99019449 | H5: =(Parameters!$C$5/Parameters!$C$4)*(1-EXP(-Parameters!$C$4*0.25))*SQRT((1-EXP(-2*Parameters!$C$4*B5))/(2*Parameters!$C$4)) -> 0.00097241305 | I5: =(1/H5)*LN(E5/(D5*G5))+H5/2 -> 0.38388635 | J5: =NORMSDIST(-I5+H5) -> 0.35089179 | K5: =NORMSDIST(-I5) -> 0.35053134 | L5: =(1+F5*0.25)*(G5*D5*J5-E5*K5) -> 0.00022737711 | M5: =L5*10000 -> 2.2737711 | O5: =IF(M5="","?",IF(ABS(M5-HW_Caplets!M5)<0.0000001,"OK","CHECK")) -> OK
B6: 0.5 | C6: 0.75 | D6: =VLOOKUP(B6,OIS_Curve!$B$19:$D$58,3,FALSE()) -> 0.98039216 | E6: =VLOOKUP(C6,OIS_Curve!$B$19:$D$58,3,FALSE()) -> 0.97157395 | F6: =Par_Rates!$E$5 -> 0.039610444 | G6: =1/(1+F6*0.25) -> 0.99019449 | H6: =(Parameters!$C$5/Parameters!$C$4)*(1-EXP(-Parameters!$C$4*0.25))*SQRT((1-EXP(-2*Parameters!$C$4*B6))/(2*Parameters!$C$4)) -> 0.0013481001 | I6: =(1/H6)*LN(E6/(D6*G6))+H6/2 -> 0.60792795 | J6: =NORMSDIST(-I6+H6) -> 0.27206489 | K6: =NORMSDIST(-I6) -> 0.27161763 | L6: =(1+F6*0.25)*(G6*D6*J6-E6*K6) -> 0.00022040156 | M6: =L6*10000 -> 2.2040156 | O6: =IF(M6="","?",IF(ABS(M6-HW_Caplets!M6)<0.0000001,"OK","CHECK")) -> OK
B7: 0.75 | C7: 1 | D7: =VLOOKUP(B7,OIS_Curve!$B$19:$D$58,3,FALSE()) -> 0.97157395 | E7: =VLOOKUP(C7,OIS_Curve!$B$19:$D$58,3,FALSE()) -> 0.96339114 | F7: =Par_Rates!$E$5 -> 0.039610444 | G7: =1/(1+F7*0.25) -> 0.99019449 | H7: =(Parameters!$C$5/Parameters!$C$4)*(1-EXP(-Parameters!$C$4*0.25))*SQRT((1-EXP(-2*Parameters!$C$4*B7))/(2*Parameters!$C$4)) -> 0.0016189875 | I7: =(1/H7)*LN(E7/(D7*G7))+H7/2 -> 0.86308085 | J7: =NORMSDIST(-I7+H7) -> 0.19449186 | K7: =NORMSDIST(-I7) -> 0.19404651 | L7: =(1+F7*0.25)*(G7*D7*J7-E7*K7) -> 0.00016931734 | M7: =L7*10000 -> 1.6931734 | O7: =IF(M7="","?",IF(ABS(M7-HW_Caplets!M7)<0.0000001,"OK","CHECK")) -> OK
B8: 1 | C8: 1.25 | D8: =VLOOKUP(B8,OIS_Curve!$B$19:$D$58,3,FALSE()) -> 0.96339114 | E8: =VLOOKUP(C8,OIS_Curve!$B$19:$D$58,3,FALSE()) -> 0.95474312 | F8: =Par_Rates!$E$5 -> 0.039610444 | G8: =1/(1+F8*0.25) -> 0.99019449 | H8: =(Parameters!$C$5/Parameters!$C$4)*(1-EXP(-Parameters!$C$4*0.25))*SQRT((1-EXP(-2*Parameters!$C$4*B8))/(2*Parameters!$C$4)) -> 0.0018336131 | I8: =(1/H8)*LN(E8/(D8*G8))+H8/2 -> 0.45724519 | J8: =NORMSDIST(-I8+H8) -> 0.32440658 | K8: =NORMSDIST(-I8) -> 0.32374741 | L8: =(1+F8*0.25)*(G8*D8*J8-E8*K8) -> 0.00037396084 | M8: =L8*10000 -> 3.7396084 | O8: =IF(M8="","?",IF(ABS(M8-HW_Caplets!M8)<0.0000001,"OK","CHECK")) -> OK
B9: 1.25 | C9: 1.5 | D9: =VLOOKUP(B9,OIS_Curve!$B$19:$D$58,3,FALSE()) -> 0.95474312 | E9: =VLOOKUP(C9,OIS_Curve!$B$19:$D$58,3,FALSE()) -> 0.94628885 | F9: =Par_Rates!$E$5 -> 0.039610444 | G9: =1/(1+F9*0.25) -> 0.99019449 | H9: =(Parameters!$C$5/Parameters!$C$4)*(1-EXP(-Parameters!$C$4*0.25))*SQRT((1-EXP(-2*Parameters!$C$4*B9))/(2*Parameters!$C$4)) -> 0.0020112979 | I9: =(1/H9)*LN(E9/(D9*G9))+H9/2 -> 0.47803068 | J9: =NORMSDIST(-I9+H9) -> 0.31703029 | K9: =NORMSDIST(-I9) -> 0.31631418 | L9: =(1+F9*0.25)*(G9*D9*J9-E9*K9) -> 0.00039380335 | M9: =L9*10000 -> 3.9380335 | O9: =IF(M9="","?",IF(ABS(M9-HW_Caplets!M9)<0.0000001,"OK","CHECK")) -> OK
B10: 1.5 | C10: 1.75 | D10: =VLOOKUP(B10,OIS_Curve!$B$19:$D$58,3,FALSE()) -> 0.94628885 | E10: =VLOOKUP(C10,OIS_Curve!$B$19:$D$58,3,FALSE()) -> 0.93802454 | F10: =Par_Rates!$E$5 -> 0.039610444 | G10: =1/(1+F10*0.25) -> 0.99019449 | H10: =(Parameters!$C$5/Parameters!$C$4)*(1-EXP(-Parameters!$C$4*0.25))*SQRT((1-EXP(-2*Parameters!$C$4*B10))/(2*Parameters!$C$4)) -> 0.0021622167 | I10: =(1/H10)*LN(E10/(D10*G10))+H10/2 -> 0.50156248 | J10: =NORMSDIST(-I10+H10) -> 0.30874872 | K10: =NORMSDIST(-I10) -> 0.30798766 | L10: =(1+F10*0.25)*(G10*D10*J10-E10*K10) -> 0.00040462284 | M10: =L10*10000 -> 4.0462284 | O10: =IF(M10="","?",IF(ABS(M10-HW_Caplets!M10)<0.0000001,"OK","CHECK")) -> OK
B11: 1.75 | C11: 2 | D11: =VLOOKUP(B11,OIS_Curve!$B$19:$D$58,3,FALSE()) -> 0.93802454 | E11: =VLOOKUP(C11,OIS_Curve!$B$19:$D$58,3,FALSE()) -> 0.92994651 | F11: =Par_Rates!$E$5 -> 0.039610444 | G11: =1/(1+F11*0.25) -> 0.99019449 | H11: =(Parameters!$C$5/Parameters!$C$4)*(1-EXP(-Parameters!$C$4*0.25))*SQRT((1-EXP(-2*Parameters!$C$4*B11))/(2*Parameters!$C$4)) -> 0.0022925715 | I11: =(1/H11)*LN(E11/(D11*G11))+H11/2 -> 0.52669539 | J11: =NORMSDIST(-I11+H11) -> 0.2999992 | K11: =NORMSDIST(-I11) -> 0.29920257 | L11: =(1+F11*0.25)*(G11*D11*J11-E11*K11) -> 0.00040889935 | M11: =L11*10000 -> 4.0889935 | O11: =IF(M11="","?",IF(ABS(M11-HW_Caplets!M11)<0.0000001,"OK","CHECK")) -> OK
B12: Cap 2Y Total (Model) | L12: =SUM(L5:L11) -> 0.0021983824 | M12: =SUM(M5:M11) -> 21.983824
B14: 3Y Cap · K = 3.670% · 11 caplets (T_start = 0.25 to 2.75)
B15: T_start | C15: T_end | D15: P(0,S) | E15: P(0,S+δ) | F15: K
B16: 0.25 | C16: 0.5 | D16: =VLOOKUP(B16,OIS_Curve!$B$19:$D$58,3,FALSE()) -> 0.98973154 | E16: =VLOOKUP(C16,OIS_Curve!$B$19:$D$58,3,FALSE()) -> 0.98039216 | F16: =Par_Rates!$E$6 -> 0.0367 | G16: =1/(1+F16*0.25) -> 0.99090842 | H16: =(Parameters!$C$5/Parameters!$C$4)*(1-EXP(-Parameters!$C$4*0.25))*SQRT((1-EXP(-2*Parameters!$C$4*B16))/(2*Parameters!$C$4)) -> 0.00097241305 | I16: =(1/H16)*LN(E16/(D16*G16))+H16/2 -> -0.35729678 | J16: =NORMSDIST(-I16+H16) -> 0.63992906 | K16: =NORMSDIST(-I16) -> 0.63956518 | L16: =(1+F16*0.25)*(G16*D16*J16-E16*K16) -> 0.00058033818 | M16: =L16*10000 -> 5.8033818 | O16: =IF(M16="","?",IF(ABS(M16-HW_Caplets!M16)<0.0000001,"OK","CHECK")) -> OK
B17: 0.5 | C17: 0.75 | D17: =VLOOKUP(B17,OIS_Curve!$B$19:$D$58,3,FALSE()) -> 0.98039216 | E17: =VLOOKUP(C17,OIS_Curve!$B$19:$D$58,3,FALSE()) -> 0.97157395 | F17: =Par_Rates!$E$6 -> 0.0367 | G17: =1/(1+F17*0.25) -> 0.99090842 | H17: =(Parameters!$C$5/Parameters!$C$4)*(1-EXP(-Parameters!$C$4*0.25))*SQRT((1-EXP(-2*Parameters!$C$4*B17))/(2*Parameters!$C$4)) -> 0.0013481001 | I17: =(1/H17)*LN(E17/(D17*G17))+H17/2 -> 0.073296939 | J17: =NORMSDIST(-I17+H17) -> 0.47132131 | K17: =NORMSDIST(-I17) -> 0.47078491 | L17: =(1+F17*0.25)*(G17*D17*J17-E17*K17) -> 0.00048069045 | M17: =L17*10000 -> 4.8069045 | O17: =IF(M17="","?",IF(ABS(M17-HW_Caplets!M17)<0.0000001,"OK","CHECK")) -> OK
B18: 0.75 | C18: 1 | D18: =VLOOKUP(B18,OIS_Curve!$B$19:$D$58,3,FALSE()) -> 0.97157395 | E18: =VLOOKUP(C18,OIS_Curve!$B$19:$D$58,3,FALSE()) -> 0.96339114 | F18: =Par_Rates!$E$6 -> 0.0367 | G18: =1/(1+F18*0.25) -> 0.99090842 | H18: =(Parameters!$C$5/Parameters!$C$4)*(1-EXP(-Parameters!$C$4*0.25))*SQRT((1-EXP(-2*Parameters!$C$4*B18))/(2*Parameters!$C$4)) -> 0.0016189875 | I18: =(1/H18)*LN(E18/(D18*G18))+H18/2 -> 0.41790376 | J18: =NORMSDIST(-I18+H18) -> 0.33860082 | K18: =NORMSDIST(-I18) -> 0.33800874 | L18: =(1+F18*0.25)*(G18*D18*J18-E18*K18) -> 0.0003534109 | M18: =L18*10000 -> 3.534109 | O18: =IF(M18="","?",IF(ABS(M18-HW_Caplets!M18)<0.0000001,"OK","CHECK")) -> OK
B19: 1 | C19: 1.25 | D19: =VLOOKUP(B19,OIS_Curve!$B$19:$D$58,3,FALSE()) -> 0.96339114 | E19: =VLOOKUP(C19,OIS_Curve!$B$19:$D$58,3,FALSE()) -> 0.95474312 | F19: =Par_Rates!$E$6 -> 0.0367 | G19: =1/(1+F19*0.25) -> 0.99090842 | H19: =(Parameters!$C$5/Parameters!$C$4)*(1-EXP(-Parameters!$C$4*0.25))*SQRT((1-EXP(-2*Parameters!$C$4*B19))/(2*Parameters!$C$4)) -> 0.0018336131 | I19: =(1/H19)*LN(E19/(D19*G19))+H19/2 -> 0.06417636 | J19: =NORMSDIST(-I19+H19) -> 0.47514494 | K19: =NORMSDIST(-I19) -> 0.4744149 | L19: =(1+F19*0.25)*(G19*D19*J19-E19*K19) -> 0.00065029983 | M19: =L19*10000 -> 6.5029983 | O19: =IF(M19="","?",IF(ABS(M19-HW_Caplets!M19)<0.0000001,"OK","CHECK")) -> OK
B20: 1.25 | C20: 1.5 | D20: =VLOOKUP(B20,OIS_Curve!$B$19:$D$58,3,FALSE()) -> 0.95474312 | E20: =VLOOKUP(C20,OIS_Curve!$B$19:$D$58,3,FALSE()) -> 0.94628885 | F20: =Par_Rates!$E$6 -> 0.0367 | G20: =1/(1+F20*0.25) -> 0.99090842 | H20: =(Parameters!$C$5/Parameters!$C$4)*(1-EXP(-Parameters!$C$4*0.25))*SQRT((1-EXP(-2*Parameters!$C$4*B20))/(2*Parameters!$C$4)) -> 0.0020112979 | I20: =(1/H20)*LN(E20/(D20*G20))+H20/2 -> 0.11968687 | J20: =NORMSDIST(-I20+H20) -> 0.45316236 | K20: =NORMSDIST(-I20) -> 0.4523656 | L20: =(1+F20*0.25)*(G20*D20*J20-E20*K20) -> 0.00065759508 | M20: =L20*10000 -> 6.5759508 | O20: =IF(M20="","?",IF(ABS(M20-HW_Caplets!M20)<0.0000001,"OK","CHECK")) -> OK
B21: 1.5 | C21: 1.75 | D21: =VLOOKUP(B21,OIS_Curve!$B$19:$D$58,3,FALSE()) -> 0.94628885 | E21: =VLOOKUP(C21,OIS_Curve!$B$19:$D$58,3,FALSE()) -> 0.93802454 | F21: =Par_Rates!$E$6 -> 0.0367 | G21: =1/(1+F21*0.25) -> 0.99090842 | H21: =(Parameters!$C$5/Parameters!$C$4)*(1-EXP(-Parameters!$C$4*0.25))*SQRT((1-EXP(-2*Parameters!$C$4*B21))/(2*Parameters!$C$4)) -> 0.0021622167 | I21: =(1/H21)*LN(E21/(D21*G21))+H21/2 -> 0.16823042 | J21: =NORMSDIST(-I21+H21) -> 0.43405164 | K21: =NORMSDIST(-I21) -> 0.43320101 | L21: =(1+F21*0.25)*(G21*D21*J21-E21*K21) -> 0.00065676274 | M21: =L21*10000 -> 6.5676274 | O21: =IF(M21="","?",IF(ABS(M21-HW_Caplets!M21)<0.0000001,"OK","CHECK")) -> OK
B22: 1.75 | C22: 2 | D22: =VLOOKUP(B22,OIS_Curve!$B$19:$D$58,3,FALSE()) -> 0.93802454 | E22: =VLOOKUP(C22,OIS_Curve!$B$19:$D$58,3,FALSE()) -> 0.92994651 | F22: =Par_Rates!$E$6 -> 0.0367 | G22: =1/(1+F22*0.25) -> 0.99090842 | H22: =(Parameters!$C$5/Parameters!$C$4)*(1-EXP(-Parameters!$C$4*0.25))*SQRT((1-EXP(-2*Parameters!$C$4*B22))/(2*Parameters!$C$4)) -> 0.0022925715 | I22: =(1/H22)*LN(E22/(D22*G22))+H22/2 -> 0.21231648 | J22: =NORMSDIST(-I22+H22) -> 0.41682451 | K22: =NORMSDIST(-I22) -> 0.41593007 | L22: =(1+F22*0.25)*(G22*D22*J22-E22*K22) -> 0.00065007615 | M22: =L22*10000 -> 6.5007615 | O22: =IF(M22="","?",IF(ABS(M22-HW_Caplets!M22)<0.0000001,"OK","CHECK")) -> OK
B23: 2 | C23: 2.25 | D23: =VLOOKUP(B23,OIS_Curve!$B$19:$D$58,3,FALSE()) -> 0.92994651 | E23: =VLOOKUP(C23,OIS_Curve!$B$19:$D$58,3,FALSE()) -> 0.92179827 | F23: =Par_Rates!$E$6 -> 0.0367 | G23: =1/(1+F23*0.25) -> 0.99090842 | H23: =(Parameters!$C$5/Parameters!$C$4)*(1-EXP(-Parameters!$C$4*0.25))*SQRT((1-EXP(-2*Parameters!$C$4*B23))/(2*Parameters!$C$4)) -> 0.0024065047 | I23: =(1/H23)*LN(E23/(D23*G23))+H23/2 -> 0.13936975 | J23: =NORMSDIST(-I23+H23) -> 0.44552992 | K23: =NORMSDIST(-I23) -> 0.44457899 | L23: =(1+F23*0.25)*(G23*D23*J23-E23*K23) -> 0.00074683052 | M23: =L23*10000 -> 7.4683052 | O23: =IF(M23="","?",IF(ABS(M23-HW_Caplets!M23)<0.0000001,"OK","CHECK")) -> OK
B24: 2.25 | C24: 2.5 | D24: =VLOOKUP(B24,OIS_Curve!$B$19:$D$58,3,FALSE()) -> 0.92179827 | E24: =VLOOKUP(C24,OIS_Curve!$B$19:$D$58,3,FALSE()) -> 0.91377784 | F24: =Par_Rates!$E$6 -> 0.0367 | G24: =1/(1+F24*0.25) -> 0.99090842 | H24: =(Parameters!$C$5/Parameters!$C$4)*(1-EXP(-Parameters!$C$4*0.25))*SQRT((1-EXP(-2*Parameters!$C$4*B24))/(2*Parameters!$C$4)) -> 0.0025069625 | I24: =(1/H24)*LN(E24/(D24*G24))+H24/2 -> 0.15851348 | J24: =NORMSDIST(-I24+H24) -> 0.43801394 | K24: =NORMSDIST(-I24) -> 0.4370261 | L24: =(1+F24*0.25)*(G24*D24*J24-E24*K24) -> 0.00075173841 | M24: =L24*10000 -> 7.5173841 | O24: =IF(M24="","?",IF(ABS(M24-HW_Caplets!M24)<0.0000001,"OK","CHECK")) -> OK
B25: 2.5 | C25: 2.75 | D25: =VLOOKUP(B25,OIS_Curve!$B$19:$D$58,3,FALSE()) -> 0.91377784 | E25: =VLOOKUP(C25,OIS_Curve!$B$19:$D$58,3,FALSE()) -> 0.90588313 | F25: =Par_Rates!$E$6 -> 0.0367 | G25: =1/(1+F25*0.25) -> 0.99090842 | H25: =(Parameters!$C$5/Parameters!$C$4)*(1-EXP(-Parameters!$C$4*0.25))*SQRT((1-EXP(-2*Parameters!$C$4*B25))/(2*Parameters!$C$4)) -> 0.0025961381 | I25: =(1/H25)*LN(E25/(D25*G25))+H25/2 -> 0.17694031 | J25: =NORMSDIST(-I25+H25) -> 0.43079749 | K25: =NORMSDIST(-I25) -> 0.42977764 | L25: =(1+F25*0.25)*(G25*D25*J25-E25*K25) -> 0.00075280309 | M25: =L25*10000 -> 7.5280309 | O25: =IF(M25="","?",IF(ABS(M25-HW_Caplets!M25)<0.0000001,"OK","CHECK")) -> OK
B26: 2.75 | C26: 3 | D26: =VLOOKUP(B26,OIS_Curve!$B$19:$D$58,3,FALSE()) -> 0.90588313 | E26: =VLOOKUP(C26,OIS_Curve!$B$19:$D$58,3,FALSE()) -> 0.89811208 | F26: =Par_Rates!$E$6 -> 0.0367 | G26: =1/(1+F26*0.25) -> 0.99090842 | H26: =(Parameters!$C$5/Parameters!$C$4)*(1-EXP(-Parameters!$C$4*0.25))*SQRT((1-EXP(-2*Parameters!$C$4*B26))/(2*Parameters!$C$4)) -> 0.002675722 | I26: =(1/H26)*LN(E26/(D26*G26))+H26/2 -> 0.19483259 | J26: =NORMSDIST(-I26+H26) -> 0.42380967 | K26: =NORMSDIST(-I26) -> 0.42276201 | L26: =(1+F26*0.25)*(G26*D26*J26-E26*K26) -> 0.00075072765 | M26: =L26*10000 -> 7.5072765 | O26: =IF(M26="","?",IF(ABS(M26-HW_Caplets!M26)<0.0000001,"OK","CHECK")) -> OK
B27: Cap 3Y Total (Model) | L27: =SUM(L16:L26) -> 0.007031273 | M27: =SUM(M16:M26) -> 70.31273
B29: 5Y Cap · K = 3.640% · 19 caplets (T_start = 0.25 to 4.75)
B30: T_start | C30: T_end | D30: P(0,S) | E30: P(0,S+δ) | F30: K
B31: 0.25 | C31: 0.5 | D31: =VLOOKUP(B31,OIS_Curve!$B$19:$D$58,3,FALSE()) -> 0.98973154 | E31: =VLOOKUP(C31,OIS_Curve!$B$19:$D$58,3,FALSE()) -> 0.98039216 | F31: =Par_Rates!$E$7 -> 0.036400127 | G31: =1/(1+F31*0.25) -> 0.99098203 | H31: =(Parameters!$C$5/Parameters!$C$4)*(1-EXP(-Parameters!$C$4*0.25))*SQRT((1-EXP(-2*Parameters!$C$4*B31))/(2*Parameters!$C$4)) -> 0.00097241305 | I31: =(1/H31)*LN(E31/(D31*G31))+H31/2 -> -0.43369367 | J31: =NORMSDIST(-I31+H31) -> 0.66809759 | K31: =NORMSDIST(-I31) -> 0.66774455 | L31: =(1+F31*0.25)*(G31*D31*J31-E31*K31) -> 0.00062838583 | M31: =L31*10000 -> 6.2838583 | O31: =IF(M31="","?",IF(ABS(M31-HW_Caplets!M31)<0.0000001,"OK","CHECK")) -> OK
B32: 0.5 | C32: 0.75 | D32: =VLOOKUP(B32,OIS_Curve!$B$19:$D$58,3,FALSE()) -> 0.98039216 | E32: =VLOOKUP(C32,OIS_Curve!$B$19:$D$58,3,FALSE()) -> 0.97157395 | F32: =Par_Rates!$E$7 -> 0.036400127 | G32: =1/(1+F32*0.25) -> 0.99098203 | H32: =(Parameters!$C$5/Parameters!$C$4)*(1-EXP(-Parameters!$C$4*0.25))*SQRT((1-EXP(-2*Parameters!$C$4*B32))/(2*Parameters!$C$4)) -> 0.0013481001 | I32: =(1/H32)*LN(E32/(D32*G32))+H32/2 -> 0.018190254 | J32: =NORMSDIST(-I32+H32) -> 0.49328127 | K32: =NORMSDIST(-I32) -> 0.49274354 | L32: =(1+F32*0.25)*(G32*D32*J32-E32*K32) -> 0.00051578041 | M32: =L32*10000 -> 5.1578041 | O32: =IF(M32="","?",IF(ABS(M32-HW_Caplets!M32)<0.0000001,"OK","CHECK")) -> OK
B33: 0.75 | C33: 1 | D33: =VLOOKUP(B33,OIS_Curve!$B$19:$D$58,3,FALSE()) -> 0.97157395 | E33: =VLOOKUP(C33,OIS_Curve!$B$19:$D$58,3,FALSE()) -> 0.96339114 | F33: =Par_Rates!$E$7 -> 0.036400127 | G33: =1/(1+F33*0.25) -> 0.99098203 | H33: =(Parameters!$C$5/Parameters!$C$4)*(1-EXP(-Parameters!$C$4*0.25))*SQRT((1-EXP(-2*Parameters!$C$4*B33))/(2*Parameters!$C$4)) -> 0.0016189875 | I33: =(1/H33)*LN(E33/(D33*G33))+H33/2 -> 0.37201747 | J33: =NORMSDIST(-I33+H33) -> 0.3555428 | K33: =NORMSDIST(-I33) -> 0.35493992 | L33: =(1+F33*0.25)*(G33*D33*J33-E33*K33) -> 0.00037843268 | M33: =L33*10000 -> 3.7843268 | O33: =IF(M33="","?",IF(ABS(M33-HW_Caplets!M33)<0.0000001,"OK","CHECK")) -> OK
B34: 1 | C34: 1.25 | D34: =VLOOKUP(B34,OIS_Curve!$B$19:$D$58,3,FALSE()) -> 0.96339114 | E34: =VLOOKUP(C34,OIS_Curve!$B$19:$D$58,3,FALSE()) -> 0.95474312 | F34: =Par_Rates!$E$7 -> 0.036400127 | G34: =1/(1+F34*0.25) -> 0.99098203 | H34: =(Parameters!$C$5/Parameters!$C$4)*(1-EXP(-Parameters!$C$4*0.25))*SQRT((1-EXP(-2*Parameters!$C$4*B34))/(2*Parameters!$C$4)) -> 0.0018336131 | I34: =(1/H34)*LN(E34/(D34*G34))+H34/2 -> 0.02366109 | J34: =NORMSDIST(-I34+H34) -> 0.49129279 | K34: =NORMSDIST(-I34) -> 0.49056147 | L34: =(1+F34*0.25)*(G34*D34*J34-E34*K34) -> 0.0006848339 | M34: =L34*10000 -> 6.848339 | O34: =IF(M34="","?",IF(ABS(M34-HW_Caplets!M34)<0.0000001,"OK","CHECK")) -> OK
B35: 1.25 | C35: 1.5 | D35: =VLOOKUP(B35,OIS_Curve!$B$19:$D$58,3,FALSE()) -> 0.95474312 | E35: =VLOOKUP(C35,OIS_Curve!$B$19:$D$58,3,FALSE()) -> 0.94628885 | F35: =Par_Rates!$E$7 -> 0.036400127 | G35: =1/(1+F35*0.25) -> 0.99098203 | H35: =(Parameters!$C$5/Parameters!$C$4)*(1-EXP(-Parameters!$C$4*0.25))*SQRT((1-EXP(-2*Parameters!$C$4*B35))/(2*Parameters!$C$4)) -> 0.0020112979 | I35: =(1/H35)*LN(E35/(D35*G35))+H35/2 -> 0.082750853 | J35: =NORMSDIST(-I35+H35) -> 0.46782454 | K35: =NORMSDIST(-I35) -> 0.46702482 | L35: =(1+F35*0.25)*(G35*D35*J35-E35*K35) -> 0.00069020622 | M35: =L35*10000 -> 6.9020622 | O35: =IF(M35="","?",IF(ABS(M35-HW_Caplets!M35)<0.0000001,"OK","CHECK")) -> OK
B36: 1.5 | C36: 1.75 | D36: =VLOOKUP(B36,OIS_Curve!$B$19:$D$58,3,FALSE()) -> 0.94628885 | E36: =VLOOKUP(C36,OIS_Curve!$B$19:$D$58,3,FALSE()) -> 0.93802454 | F36: =Par_Rates!$E$7 -> 0.036400127 | G36: =1/(1+F36*0.25) -> 0.99098203 | H36: =(Parameters!$C$5/Parameters!$C$4)*(1-EXP(-Parameters!$C$4*0.25))*SQRT((1-EXP(-2*Parameters!$C$4*B36))/(2*Parameters!$C$4)) -> 0.0021622167 | I36: =(1/H36)*LN(E36/(D36*G36))+H36/2 -> 0.13387247 | J36: =NORMSDIST(-I36+H36) -> 0.44760674 | K36: =NORMSDIST(-I36) -> 0.44675171 | L36: =(1+F36*0.25)*(G36*D36*J36-E36*K36) -> 0.00068770232 | M36: =L36*10000 -> 6.8770232 | O36: =IF(M36="","?",IF(ABS(M36-HW_Caplets!M36)<0.0000001,"OK","CHECK")) -> OK
B37: 1.75 | C37: 2 | D37: =VLOOKUP(B37,OIS_Curve!$B$19:$D$58,3,FALSE()) -> 0.93802454 | E37: =VLOOKUP(C37,OIS_Curve!$B$19:$D$58,3,FALSE()) -> 0.92994651 | F37: =Par_Rates!$E$7 -> 0.036400127 | G37: =1/(1+F37*0.25) -> 0.99098203 | H37: =(Parameters!$C$5/Parameters!$C$4)*(1-EXP(-Parameters!$C$4*0.25))*SQRT((1-EXP(-2*Parameters!$C$4*B37))/(2*Parameters!$C$4)) -> 0.0022925715 | I37: =(1/H37)*LN(E37/(D37*G37))+H37/2 -> 0.17991211 | J37: =NORMSDIST(-I37+H37) -> 0.42951089 | K37: =NORMSDIST(-I37) -> 0.42861078 | L37: =(1+F37*0.25)*(G37*D37*J37-E37*K37) -> 0.00067951484 | M37: =L37*10000 -> 6.7951484 | O37: =IF(M37="","?",IF(ABS(M37-HW_Caplets!M37)<0.0000001,"OK","CHECK")) -> OK
B38: 2 | C38: 2.25 | D38: =VLOOKUP(B38,OIS_Curve!$B$19:$D$58,3,FALSE()) -> 0.92994651 | E38: =VLOOKUP(C38,OIS_Curve!$B$19:$D$58,3,FALSE()) -> 0.92179827 | F38: =Par_Rates!$E$7 -> 0.036400127 | G38: =1/(1+F38*0.25) -> 0.99098203 | H38: =(Parameters!$C$5/Parameters!$C$4)*(1-EXP(-Parameters!$C$4*0.25))*SQRT((1-EXP(-2*Parameters!$C$4*B38))/(2*Parameters!$C$4)) -> 0.0024065047 | I38: =(1/H38)*LN(E38/(D38*G38))+H38/2 -> 0.10849953 | J38: =NORMSDIST(-I38+H38) -> 0.45775427 | K38: =NORMSDIST(-I38) -> 0.45679973 | L38: =(1+F38*0.25)*(G38*D38*J38-E38*K38) -> 0.00077797537 | M38: =L38*10000 -> 7.7797537 | O38: =IF(M38="","?",IF(ABS(M38-HW_Caplets!M38)<0.0000001,"OK","CHECK")) -> OK
B39: 2.25 | C39: 2.5 | D39: =VLOOKUP(B39,OIS_Curve!$B$19:$D$58,3,FALSE()) -> 0.92179827 | E39: =VLOOKUP(C39,OIS_Curve!$B$19:$D$58,3,FALSE()) -> 0.91377784 | F39: =Par_Rates!$E$7 -> 0.036400127 | G39: =1/(1+F39*0.25) -> 0.99098203 | H39: =(Parameters!$C$5/Parameters!$C$4)*(1-EXP(-Parameters!$C$4*0.25))*SQRT((1-EXP(-2*Parameters!$C$4*B39))/(2*Parameters!$C$4)) -> 0.0025069625 | I39: =(1/H39)*LN(E39/(D39*G39))+H39/2 -> 0.12888028 | J39: =NORMSDIST(-I39+H39) -> 0.44971821 | K39: =NORMSDIST(-I39) -> 0.44872619 | L39: =(1+F39*0.25)*(G39*D39*J39-E39*K39) -> 0.00078207701 | M39: =L39*10000 -> 7.8207701 | O39: =IF(M39="","?",IF(ABS(M39-HW_Caplets!M39)<0.0000001,"OK","CHECK")) -> OK
B40: 2.5 | C40: 2.75 | D40: =VLOOKUP(B40,OIS_Curve!$B$19:$D$58,3,FALSE()) -> 0.91377784 | E40: =VLOOKUP(C40,OIS_Curve!$B$19:$D$58,3,FALSE()) -> 0.90588313 | F40: =Par_Rates!$E$7 -> 0.036400127 | G40: =1/(1+F40*0.25) -> 0.99098203 | H40: =(Parameters!$C$5/Parameters!$C$4)*(1-EXP(-Parameters!$C$4*0.25))*SQRT((1-EXP(-2*Parameters!$C$4*B40))/(2*Parameters!$C$4)) -> 0.0025961381 | I40: =(1/H40)*LN(E40/(D40*G40))+H40/2 -> 0.14832498 | J40: =NORMSDIST(-I40+H40) -> 0.44206772 | K40: =NORMSDIST(-I40) -> 0.44104315 | L40: =(1+F40*0.25)*(G40*D40*J40-E40*K40) -> 0.00078237254 | M40: =L40*10000 -> 7.8237254 | O40: =IF(M40="","?",IF(ABS(M40-HW_Caplets!M40)<0.0000001,"OK","CHECK")) -> OK
B41: 2.75 | C41: 3 | D41: =VLOOKUP(B41,OIS_Curve!$B$19:$D$58,3,FALSE()) -> 0.90588313 | E41: =VLOOKUP(C41,OIS_Curve!$B$19:$D$58,3,FALSE()) -> 0.89811208 | F41: =Par_Rates!$E$7 -> 0.036400127 | G41: =1/(1+F41*0.25) -> 0.99098203 | H41: =(Parameters!$C$5/Parameters!$C$4)*(1-EXP(-Parameters!$C$4*0.25))*SQRT((1-EXP(-2*Parameters!$C$4*B41))/(2*Parameters!$C$4)) -> 0.002675722 | I41: =(1/H41)*LN(E41/(D41*G41))+H41/2 -> 0.16706837 | J41: =NORMSDIST(-I41+H41) -> 0.43471103 | K41: =NORMSDIST(-I41) -> 0.43365813 | L41: =(1+F41*0.25)*(G41*D41*J41-E41*K41) -> 0.00077955864 | M41: =L41*10000 -> 7.7955864 | O41: =IF(M41="","?",IF(ABS(M41-HW_Caplets!M41)<0.0000001,"OK","CHECK")) -> OK
B42: 3 | C42: 3.25 | D42: =VLOOKUP(B42,OIS_Curve!$B$19:$D$58,3,FALSE()) -> 0.89811208 | E42: =VLOOKUP(C42,OIS_Curve!$B$19:$D$58,3,FALSE()) -> 0.89004033 | F42: =Par_Rates!$E$7 -> 0.036400127 | G42: =1/(1+F42*0.25) -> 0.99098203 | H42: =(Parameters!$C$5/Parameters!$C$4)*(1-EXP(-Parameters!$C$4*0.25))*SQRT((1-EXP(-2*Parameters!$C$4*B42))/(2*Parameters!$C$4)) -> 0.0027470527 | I42: =(1/H42)*LN(E42/(D42*G42))+H42/2 -> 0.012575352 | J42: =NORMSDIST(-I42+H42) -> 0.49607914 | K42: =NORMSDIST(-I42) -> 0.49498329 | L42: =(1+F42*0.25)*(G42*D42*J42-E42*K42) -> 0.00097051294 | M42: =L42*10000 -> 9.7051294 | O42: =IF(M42="","?",IF(ABS(M42-HW_Caplets!M42)<0.0000001,"OK","CHECK")) -> OK
...

Sheet Cap_Prices
B1: Cap Prices · Model vs Market · SSE → Solver Target
B3: Cap Maturity | C3: Market Price (bps) | D3: Model Price (bps) | E3: Error (bps) | F3: Squared Error
